Workbook
Name Descricao: Tabela4[Descrição (opcional)]
Name Entrada: tb_entradas[Entradas]
Name NativeTimeline_Data: #N/A
Name Saída: tb_saidas[Saídas]
Name Saldo_Inicial: Auxiliar!$AI$4
Name SegmentaçãodeDados_Categoria: #N/A
Name SegmentaçãodeDados_Tipo: #N/A

Sheet Base
B1: Fluxo de Caixa | K1: =Saldo_Inicial+SUMIF(Tab_Base[Tipo],"Entrada",Tab_Base[Valor])-SUMIF(Tab_Base[Tipo],"Saída",Tab_Base[Valor]) -> 70.88
G2: Entradas | H2: Saídas | I2: Saldo
B3: Movimentações Diárias | G3: =SUMPRODUCT(SUBTOTAL(9,OFFSET(F6,ROW(Tab_Base[Valor])-ROW(F6),0)),(Tab_Base[Tipo]="Entrada")+0) -> 4996.49 | H3: =SUMPRODUCT(SUBTOTAL(9,OFFSET(F6,ROW(Tab_Base[Valor])-ROW(F6),0)),(Tab_Base[Tipo]="Saída")+0) -> 4925.68 | I3: =G3-H3 -> 70.81
B5: Data | C5: Tipo | D5: Categoria | E5: Descrição | F5: Valor | G5: Mês | H5: Ano
B6: 45573 | C6: Entrada | D6: Salário | E6: R$2.500,00 - FGTS descontado | F6: 2296 | G6: =IF(Tab_Base[[#This Row],[Data]]<>"",MONTH(Tab_Base[[#This Row],[Data]]),"-") -> 10 | H6: =IF(Tab_Base[[#This Row],[Data]]<>"",YEAR(Tab_Base[[#This Row],[Data]]),"-") -> 2024
B7: 45573 | C7: Saída | D7: Fatura Cartão | F7: 785.96 | G7: =IF(Tab_Base[[#This Row],[Data]]<>"",MONTH(Tab_Base[[#This Row],[Data]]),"-") -> 10 | H7: =IF(Tab_Base[[#This Row],[Data]]<>"",YEAR(Tab_Base[[#This Row],[Data]]),"-") -> 2024
B8: 45573 | C8: Saída | D8: Pix Anderson | E8: Parcela 6/8 | F8: 200 | G8: =IF(Tab_Base[[#This Row],[Data]]<>"",MONTH(Tab_Base[[#This Row],[Data]]),"-") -> 10 | H8: =IF(Tab_Base[[#This Row],[Data]]<>"",YEAR(Tab_Base[[#This Row],[Data]]),"-") -> 2024
B9: 45573 | C9: Saída | D9: Internet | E9: R$109,90 - Desconto | F9: 99.9 | G9: =IF(Tab_Base[[#This Row],[Data]]<>"",MONTH(Tab_Base[[#This Row],[Data]]),"-") -> 10 | H9: =IF(Tab_Base[[#This Row],[Data]]<>"",YEAR(Tab_Base[[#This Row],[Data]]),"-") -> 2024
B10: 45573 | C10: Saída | D10: Parcela CNH | E10: Última parcela da carta | F10: 388 | G10: =IF(Tab_Base[[#This Row],[Data]]<>"",MONTH(Tab_Base[[#This Row],[Data]]),"-") -> 10 | H10: =IF(Tab_Base[[#This Row],[Data]]<>"",YEAR(Tab_Base[[#This Row],[Data]]),"-") -> 2024
B11: 45573 | C11: Saída | D11: Caixinha Faculdade | F11: 50 | G11: =IF(Tab_Base[[#This Row],[Data]]<>"",MONTH(Tab_Base[[#This Row],[Data]]),"-") -> 10 | H11: =IF(Tab_Base[[#This Row],[Data]]<>"",YEAR(Tab_Base[[#This Row],[Data]]),"-") -> 2024
B12: 45573 | C12: Saída | D12: Juliana Bofi - Clínica Dentista | E12: Última parcela da clínica | F12: 320 | G12: =IF(Tab_Base[[#This Row],[Data]]<>"",MONTH(Tab_Base[[#This Row],[Data]]),"-") -> 10 | H12: =IF(Tab_Base[[#This Row],[Data]]<>"",YEAR(Tab_Base[[#This Row],[Data]]),"-") -> 2024
B13: 45573 | C13: Saída | D13: Investimento CDB | F13: 330 | G13: =IF(Tab_Base[[#This Row],[Data]]<>"",MONTH(Tab_Base[[#This Row],[Data]]),"-") -> 10 | H13: =IF(Tab_Base[[#This Row],[Data]]<>"",YEAR(Tab_Base[[#This Row],[Data]]),"-") -> 2024
B14: 45573 | C14: Saída | D14: Mercado | E14: Horário de janta trabalho | F14: 5.5 | G14: =IF(Tab_Base[[#This Row],[Data]]<>"",MONTH(Tab_Base[[#This Row],[Data]]),"-") -> 10 | H14: =IF(Tab_Base[[#This Row],[Data]]<>"",YEAR(Tab_Base[[#This Row],[Data]]),"-") -> 2024
B15: 45574 | C15: Saída | D15: Cantina Microlins | E15: Horário de janta trabalho | F15: 2.5 | G15: =IF(Tab_Base[[#This Row],[Data]]<>"",MONTH(Tab_Base[[#This Row],[Data]]),"-") -> 10 | H15: =IF(Tab_Base[[#This Row],[Data]]<>"",YEAR(Tab_Base[[#This Row],[Data]]),"-") -> 2024
B16: 45574 | C16: Saída | D16: Cantina Microlins | E16: Horário de janta trabalho | F16: 2 | G16: =IF(Tab_Base[[#This Row],[Data]]<>"",MONTH(Tab_Base[[#This Row],[Data]]),"-") -> 10 | H16: =IF(Tab_Base[[#This Row],[Data]]<>"",YEAR(Tab_Base[[#This Row],[Data]]),"-") -> 2024
B17: 45575 | C17: Saída | D17: Mercado | E17: Café da manhã | F17: 28.28 | G17: =IF(Tab_Base[[#This Row],[Data]]<>"",MONTH(Tab_Base[[#This Row],[Data]]),"-") -> 10 | H17: =IF(Tab_Base[[#This Row],[Data]]<>"",YEAR(Tab_Base[[#This Row],[Data]]),"-") -> 2024
B18: 45576 | C18: Saída | D18: Cabelo | E18: Corte de cabelo | F18: 50 | G18: =IF(Tab_Base[[#This Row],[Data]]<>"",MONTH(Tab_Base[[#This Row],[Data]]),"-") -> 10 | H18: =IF(Tab_Base[[#This Row],[Data]]<>"",YEAR(Tab_Base[[#This Row],[Data]]),"-") -> 2024
B19: 45576 | C19: Entrada | D19: Resgate RDB | E19: Caixinha da faculdade | F19: 354.49 | G19: =IF(Tab_Base[[#This Row],[Data]]<>"",MONTH(Tab_Base[[#This Row],[Data]]),"-") -> 10 | H19: =IF(Tab_Base[[#This Row],[Data]]<>"",YEAR(Tab_Base[[#This Row],[Data]]),"-") -> 2024
B20: 45576 | C20: Saída | D20: Fatura Cartão | E20: Adiantei pagar essa fatura que ainda não fechou | F20: 371.76 | G20: =IF(Tab_Base[[#This Row],[Data]]<>"",MONTH(Tab_Base[[#This Row],[Data]]),"-") -> 10 | H20: =IF(Tab_Base[[#This Row],[Data]]<>"",YEAR(Tab_Base[[#This Row],[Data]]),"-") -> 2024
B21: 45579 | C21: Saída | D21: Outros | E21: Pix pra testar se funcionava | F21: 1 | G21: =IF(Tab_Base[[#This Row],[Data]]<>"",MONTH(Tab_Base[[#This Row],[Data]]),"-") -> 10 | H21: =IF(Tab_Base[[#This Row],[Data]]<>"",YEAR(Tab_Base[[#This Row],[Data]]),"-") -> 2024
B22: 45583 | C22: Saída | D22: Mercado | E22: São Paulo - Algo para comer | F22: 11 | G22: =IF(Tab_Base[[#This Row],[Data]]<>"",MONTH(Tab_Base[[#This Row],[Data]]),"-") -> 10 | H22: =IF(Tab_Base[[#This Row],[Data]]<>"",YEAR(Tab_Base[[#This Row],[Data]]),"-") -> 2024
B23: 45587 | C23: Saída | D23: Cantina Microlins | F23: 2.5 | G23: =IF(Tab_Base[[#This Row],[Data]]<>"",MONTH(Tab_Base[[#This Row],[Data]]),"-") -> 10 | H23: =IF(Tab_Base[[#This Row],[Data]]<>"",YEAR(Tab_Base[[#This Row],[Data]]),"-") -> 2024
B24: 45604 | C24: Entrada | D24: Salário | F24: 2296 | G24: =IF(Tab_Base[[#This Row],[Data]]<>"",MONTH(Tab_Base[[#This Row],[Data]]),"-") -> 11 | H24: =IF(Tab_Base[[#This Row],[Data]]<>"",YEAR(Tab_Base[[#This Row],[Data]]),"-") -> 2024
B25: 45604 | C25: Saída | D25: Outros | E25: Pix do Anderson. 07º parcela | F25: 200 | G25: =IF(Tab_Base[[#This Row],[Data]]<>"",MONTH(Tab_Base[[#This Row],[Data]]),"-") -> 11 | H25: =IF(Tab_Base[[#This Row],[Data]]<>"",YEAR(Tab_Base[[#This Row],[Data]]),"-") -> 2024
B26: 45604 | C26: Saída | D26: Fatura Cartão | E26: Fatura fechada do mês de outubro | F26: 1975.23 | G26: =IF(Tab_Base[[#This Row],[Data]]<>"",MONTH(Tab_Base[[#This Row],[Data]]),"-") -> 11 | H26: =IF(Tab_Base[[#This Row],[Data]]<>"",YEAR(Tab_Base[[#This Row],[Data]]),"-") -> 2024
B27: 45604 | C27: Saída | D27: Internet | F27: 99.9 | G27: =IF(Tab_Base[[#This Row],[Data]]<>"",MONTH(Tab_Base[[#This Row],[Data]]),"-") -> 11 | H27: =IF(Tab_Base[[#This Row],[Data]]<>"",YEAR(Tab_Base[[#This Row],[Data]]),"-") -> 2024
B28: 45601 | C28: Entrada | D28: Serviço Extra | E28: Desbloqueio de celular | F28: 50 | G28: =IF(Tab_Base[[#This Row],[Data]]<>"",MONTH(Tab_Base[[#This Row],[Data]]),"-") -> 11 | H28: =IF(Tab_Base[[#This Row],[Data]]<>"",YEAR(Tab_Base[[#This Row],[Data]]),"-") -> 2024
B29: 45605 | C29: Saída | D29: Cantina Microlins | F29: 2.15 | G29: =IF(Tab_Base[[#This Row],[Data]]<>"",MONTH(Tab_Base[[#This Row],[Data]]),"-") -> 11 | H29: =IF(Tab_Base[[#This Row],[Data]]<>"",YEAR(Tab_Base[[#This Row],[Data]]),"-") -> 2024
G30: =IF(Tab_Base[[#This Row],[Data]]<>"",MONTH(Tab_Base[[#This Row],[Data]]),"-") -> - | H30: =IF(Tab_Base[[#This Row],[Data]]<>"",YEAR(Tab_Base[[#This Row],[Data]]),"-") -> -
G31: =IF(Tab_Base[[#This Row],[Data]]<>"",MONTH(Tab_Base[[#This Row],[Data]]),"-") -> - | H31: =IF(Tab_Base[[#This Row],[Data]]<>"",YEAR(Tab_Base[[#This Row],[Data]]),"-") -> -
G32: =IF(Tab_Base[[#This Row],[Data]]<>"",MONTH(Tab_Base[[#This Row],[Data]]),"-") -> - | H32: =IF(Tab_Base[[#This Row],[Data]]<>"",YEAR(Tab_Base[[#This Row],[Data]]),"-") -> -
G33: =IF(Tab_Base[[#This Row],[Data]]<>"",MONTH(Tab_Base[[#This Row],[Data]]),"-") -> - | H33: =IF(Tab_Base[[#This Row],[Data]]<>"",YEAR(Tab_Base[[#This Row],[Data]]),"-") -> -
G34: =IF(Tab_Base[[#This Row],[Data]]<>"",MONTH(Tab_Base[[#This Row],[Data]]),"-") -> - | H34: =IF(Tab_Base[[#This Row],[Data]]<>"",YEAR(Tab_Base[[#This Row],[Data]]),"-") -> -
G35: =IF(Tab_Base[[#This Row],[Data]]<>"",MONTH(Tab_Base[[#This Row],[Data]]),"-") -> - | H35: =IF(Tab_Base[[#This Row],[Data]]<>"",YEAR(Tab_Base[[#This Row],[Data]]),"-") -> -
G36: =IF(Tab_Base[[#This Row],[Data]]<>"",MONTH(Tab_Base[[#This Row],[Data]]),"-") -> - | H36: =IF(Tab_Base[[#This Row],[Data]]<>"",YEAR(Tab_Base[[#This Row],[Data]]),"-") -> -
G37: =IF(Tab_Base[[#This Row],[Data]]<>"",MONTH(Tab_Base[[#This Row],[Data]]),"-") -> - | H37: =IF(Tab_Base[[#This Row],[Data]]<>"",YEAR(Tab_Base[[#This Row],[Data]]),"-") -> -
G38: =IF(Tab_Base[[#This Row],[Data]]<>"",MONTH(Tab_Base[[#This Row],[Data]]),"-") -> - | H38: =IF(Tab_Base[[#This Row],[Data]]<>"",YEAR(Tab_Base[[#This Row],[Data]]),"-") -> -
G39: =IF(Tab_Base[[#This Row],[Data]]<>"",MONTH(Tab_Base[[#This Row],[Data]]),"-") -> - | H39: =IF(Tab_Base[[#This Row],[Data]]<>"",YEAR(Tab_Base[[#This Row],[Data]]),"-") -> -
G40: =IF(Tab_Base[[#This Row],[Data]]<>"",MONTH(Tab_Base[[#This Row],[Data]]),"-") -> - | H40: =IF(Tab_Base[[#This Row],[Data]]<>"",YEAR(Tab_Base[[#This Row],[Data]]),"-") -> -
G41: =IF(Tab_Base[[#This Row],[Data]]<>"",MONTH(Tab_Base[[#This Row],[Data]]),"-") -> - | H41: =IF(Tab_Base[[#This Row],[Data]]<>"",YEAR(Tab_Base[[#This Row],[Data]]),"-") -> -
...

Sheet DashBoard
C2: Análise Anual
C3: 2024
C5: Entradas | D5: =Auxiliar!AE1 -> 4642
C6: Saídas | D6: =Auxiliar!O1 -> 4620.75
C7: Lucro | D7: =D5-D6 -> 21.25
C11: Análise de Período Específico | I11: Data Inicial | J11: 45566 | L11: Data Final | M11: 45657 | R11: Lucro | S11: =D20-S25 -> -283.68
C13: Top Entradas | D13: Valor | R13: Top Saídas | S13: Valor
B14: 1 | C14: {=IFERROR(INDEX(tb_entradas[Entradas],SMALL(IF(tb_entradas[Total Per]=D14,ROW(tb_entradas[Total Per])-4),COUNTIF($D$14:D14,D14))),"-")} -> Salário | D14: =IFERROR(LARGE(tb_entradas[Total Per],B14),"-") -> 4592 | Q14: 1 | R14: {=IFERROR(INDEX(tb_saidas[Saídas],SMALL(IF(tb_saidas[Total Per]=S14,ROW(tb_saidas[Total Per])-4),COUNTIF($S$14:S14,S14))),"-")} -> Fatura Cartão | S14: =IFERROR(LARGE(tb_saidas[Total Per],Q14),"-") -> 3132.95
B15: 2 | C15: {=IFERROR(INDEX(tb_entradas[Entradas],SMALL(IF(tb_entradas[Total Per]=D15,ROW(tb_entradas[Total Per])-4),COUNTIF($D$14:D15,D15))),"-")} -> Serviço Extra | D15: =IFERROR(LARGE(tb_entradas[Total Per],B15),"-") -> 50 | Q15: 2 | R15: {=IFERROR(INDEX(tb_saidas[Saídas],SMALL(IF(tb_saidas[Total Per]=S15,ROW(tb_saidas[Total Per])-4),COUNTIF($S$14:S15,S15))),"-")} -> Parcela CNH | S15: =IFERROR(LARGE(tb_saidas[Total Per],Q15),"-") -> 388
B16: 3 | C16: {=IFERROR(INDEX(tb_entradas[Entradas],SMALL(IF(tb_entradas[Total Per]=D16,ROW(tb_entradas[Total Per])-4),COUNTIF($D$14:D16,D16))),"-")} -> 0 | D16: =IFERROR(LARGE(tb_entradas[Total Per],B16),"-") -> 0 | Q16: 3 | R16: {=IFERROR(INDEX(tb_saidas[Saídas],SMALL(IF(tb_saidas[Total Per]=S16,ROW(tb_saidas[Total Per])-4),COUNTIF($S$14:S16,S16))),"-")} -> Investimento CDB | S16: =IFERROR(LARGE(tb_saidas[Total Per],Q16),"-") -> 330
B17: 4 | C17: {=IFERROR(INDEX(tb_entradas[Entradas],SMALL(IF(tb_entradas[Total Per]=D17,ROW(tb_entradas[Total Per])-4),COUNTIF($D$14:D17,D17))),"-")} -> - | D17: =IFERROR(LARGE(tb_entradas[Total Per],B17),"-") -> - | Q17: 4 | R17: {=IFERROR(INDEX(tb_saidas[Saídas],SMALL(IF(tb_saidas[Total Per]=S17,ROW(tb_saidas[Total Per])-4),COUNTIF($S$14:S17,S17))),"-")} -> Juliana Bofi - Clínica Dentista | S17: =IFERROR(LARGE(tb_saidas[Total Per],Q17),"-") -> 320
B18: 5 | C18: {=IFERROR(INDEX(tb_entradas[Entradas],SMALL(IF(tb_entradas[Total Per]=D18,ROW(tb_entradas[Total Per])-4),COUNTIF($D$14:D18,D18))),"-")} -> - | D18: =IFERROR(LARGE(tb_entradas[Total Per],B18),"-") -> - | Q18: 5 | R18: {=IFERROR(INDEX(tb_saidas[Saídas],SMALL(IF(tb_saidas[Total Per]=S18,ROW(tb_saidas[Total Per])-4),COUNTIF($S$14:S18,S18))),"-")} -> Outros | S18: =IFERROR(LARGE(tb_saidas[Total Per],Q18),"-") -> 201
C19: Demais | D19: =D20-SUM(D14:D18) -> 0 | Q19: 6 | R19: {=IFERROR(INDEX(tb_saidas[Saídas],SMALL(IF(tb_saidas[Total Per]=S19,ROW(tb_saidas[Total Per])-4),COUNTIF($S$14:S19,S19))),"-")} -> Pix Anderson | S19: =IFERROR(LARGE(tb_saidas[Total Per],Q19),"-") -> 200
C20: Total | D20: =Auxiliar!AF1 -> 4642 | Q20: 7 | R20: {=IFERROR(INDEX(tb_saidas[Saídas],SMALL(IF(tb_saidas[Total Per]=S20,ROW(tb_saidas[Total Per])-4),COUNTIF($S$14:S20,S20))),"-")} -> Internet | S20: =IFERROR(LARGE(tb_saidas[Total Per],Q20),"-") -> 199.8
Q21: 8 | R21: {=IFERROR(INDEX(tb_saidas[Saídas],SMALL(IF(tb_saidas[Total Per]=S21,ROW(tb_saidas[Total Per])-4),COUNTIF($S$14:S21,S21))),"-")} -> Caixinha Faculdade | S21: =IFERROR(LARGE(tb_saidas[Total Per],Q21),"-") -> 50
Q22: 9 | R22: {=IFERROR(INDEX(tb_saidas[Saídas],SMALL(IF(tb_saidas[Total Per]=S22,ROW(tb_saidas[Total Per])-4),COUNTIF($S$14:S22,S22))),"-")} -> Cabelo | S22: =IFERROR(LARGE(tb_saidas[Total Per],Q22),"-") -> 50
Q23: 10 | R23: {=IFERROR(INDEX(tb_saidas[Saídas],SMALL(IF(tb_saidas[Total Per]=S23,ROW(tb_saidas[Total Per])-4),COUNTIF($S$14:S23,S23))),"-")} -> Mercado | S23: =IFERROR(LARGE(tb_saidas[Total Per],Q23),"-") -> 44.78
R24: Demais | S24: =S25-SUM(S14:S23) -> 9.15
R25: Total | S25: =Auxiliar!P1 -> 4925.68

Sheet Tabela Dinâmica
B3: Centros de Custo | C3: Soma de Valor
B4: Salário | C4: 2296
B5: R$2.500,00 - FGTS descontado | C5: 2296
B6: Fatura Cartão | C6: 1157.72
B7: (vazio) | C7: 785.96
B8: Adiantei pagar essa fatura que ainda não fechou | C8: 371.76
B9: Pix Anderson | C9: 200
B10: Parcela 6/8 | C10: 200
B11: Internet | C11: 99.9
B12: R$109,90 - Desconto | C12: 99.9
B13: Parcela CNH | C13: 388
B14: Última parcela da carta | C14: 388
B15: Caixinha Faculdade | C15: 50
... B34: Total Geral | C34: 5298.89

Sheet Resultado Diário
A1: Mês | B1: Data | C1: Último Dia Mês | D1: Dia | F1: JANEIRO | G1: FEVEREIRO | H1: MARÇO | I1: ABRIL | J1: MAIO | K1: JUNHO | L1: JULHO | M1: AGOSTO | N1: SETEMBRO | O1: OUTUBRO | P1: NOVEMBRO | Q1: DEZEMBRO
A2: =HLOOKUP(F5,F1:Q2,2,FALSE) -> 11 | B2: =DATE(D5,A2,1) -> 45597 | C2: =EOMONTH(B2,0) -> 45626 | D2: =DAY(C2) -> 30 | F2: 1 | G2: 2 | H2: 3 | I2: 4 | J2: 5 | K2: 6 | L2: 7 | M2: 8 | N2: 9 | O2: 10 | P2: 11 | Q2: 12
B3: Resultado Diário
C5: Ano | D5: 2024 | E5: Mês | F5: Novembro
B7: Dia | C7: Dia | D7: Entradas | E7: Saídas | F7: Saldo
B8: 1 | C8: =IFERROR(DATE($D$5,$A$2,B8),"-") -> 45597 | D8: =SUMIFS(Tab_Base[Valor],Tab_Base[Data],DATE($D$5,$A$2,B8),Tab_Base[Tipo],"Entrada") -> 0 | E8: =SUMIFS(Tab_Base[Valor],Tab_Base[Data],DATE($D$5,$A$2,B8),Tab_Base[Tipo],"Saída") -> 0 | F8: =D8-E8 -> 0
B9: 2 | C9: =IFERROR(DATE($D$5,$A$2,B9),"-") -> 45598 | D9: =SUMIFS(Tab_Base[Valor],Tab_Base[Data],DATE($D$5,$A$2,B9),Tab_Base[Tipo],"Entrada") -> 0 | E9: =SUMIFS(Tab_Base[Valor],Tab_Base[Data],DATE($D$5,$A$2,B9),Tab_Base[Tipo],"Saída") -> 0 | F9: =D9-E9 -> 0 | J9: Relatório Mensal
B10: 3 | C10: =IFERROR(DATE($D$5,$A$2,B10),"-") -> 45599 | D10: =SUMIFS(Tab_Base[Valor],Tab_Base[Data],DATE($D$5,$A$2,B10),Tab_Base[Tipo],"Entrada") -> 0 | E10: =SUMIFS(Tab_Base[Valor],Tab_Base[Data],DATE($D$5,$A$2,B10),Tab_Base[Tipo],"Saída") -> 0 | F10: =D10-E10 -> 0
B11: 4 | C11: =IFERROR(DATE($D$5,$A$2,B11),"-") -> 45600 | D11: =SUMIFS(Tab_Base[Valor],Tab_Base[Data],DATE($D$5,$A$2,B11),Tab_Base[Tipo],"Entrada") -> 0 | E11: =SUMIFS(Tab_Base[Valor],Tab_Base[Data],DATE($D$5,$A$2,B11),Tab_Base[Tipo],"Saída") -> 0 | F11: =D11-E11 -> 0 | J11: Entradas | K11: Saídas | L11: Saldo
B12: 5 | C12: =IFERROR(DATE($D$5,$A$2,B12),"-") -> 45601 | D12: =SUMIFS(Tab_Base[Valor],Tab_Base[Data],DATE($D$5,$A$2,B12),Tab_Base[Tipo],"Entrada") -> 50 | E12: =SUMIFS(Tab_Base[Valor],Tab_Base[Data],DATE($D$5,$A$2,B12),Tab_Base[Tipo],"Saída") -> 0 | F12: =D12-E12 -> 50 | H12: 1 | I12: Janeiro | J12: =SUMIFS(Tab_Base[Valor],Tab_Base[Ano],$D$5,Tab_Base[Mês],H12,Tab_Base[Tipo],"Entrada") -> 0 | K12: =SUMIFS(Tab_Base[Valor],Tab_Base[Ano],$D$5,Tab_Base[Mês],H12,Tab_Base[Tipo],"Saída") -> 0 | L12: =J12-K12 -> 0
B13: 6 | C13: =IFERROR(DATE($D$5,$A$2,B13),"-") -> 45602 | D13: =SUMIFS(Tab_Base[Valor],Tab_Base[Data],DATE($D$5,$A$2,B13),Tab_Base[Tipo],"Entrada") -> 0 | E13: =SUMIFS(Tab_Base[Valor],Tab_Base[Data],DATE($D$5,$A$2,B13),Tab_Base[Tipo],"Saída") -> 0 | F13: =D13-E13 -> 0 | H13: 2 | I13: Fevereiro | J13: =SUMIFS(Tab_Base[Valor],Tab_Base[Ano],$D$5,Tab_Base[Mês],H13,Tab_Base[Tipo],"Entrada") -> 0 | K13: =SUMIFS(Tab_Base[Valor],Tab_Base[Ano],$D$5,Tab_Base[Mês],H13,Tab_Base[Tipo],"Saída") -> 0 | L13: =J13-K13 -> 0
B14: 7 | C14: =IFERROR(DATE($D$5,$A$2,B14),"-") -> 45603 | D14: =SUMIFS(Tab_Base[Valor],Tab_Base[Data],DATE($D$5,$A$2,B14),Tab_Base[Tipo],"Entrada") -> 0 | E14: =SUMIFS(Tab_Base[Valor],Tab_Base[Data],DATE($D$5,$A$2,B14),Tab_Base[Tipo],"Saída") -> 0 | F14: =D14-E14 -> 0 | H14: 3 | I14: Março | J14: =SUMIFS(Tab_Base[Valor],Tab_Base[Ano],$D$5,Tab_Base[Mês],H14,Tab_Base[Tipo],"Entrada") -> 0 | K14: =SUMIFS(Tab_Base[Valor],Tab_Base[Ano],$D$5,Tab_Base[Mês],H14,Tab_Base[Tipo],"Saída") -> 0 | L14: =J14-K14 -> 0
B15: 8 | C15: =IFERROR(DATE($D$5,$A$2,B15),"-") -> 45604 | D15: =SUMIFS(Tab_Base[Valor],Tab_Base[Data],DATE($D$5,$A$2,B15),Tab_Base[Tipo],"Entrada") -> 2296 | E15: =SUMIFS(Tab_Base[Valor],Tab_Base[Data],DATE($D$5,$A$2,B15),Tab_Base[Tipo],"Saída") -> 2275.13 | F15: =D15-E15 -> 20.87 | H15: 4 | I15: Abril | J15: =SUMIFS(Tab_Base[Valor],Tab_Base[Ano],$D$5,Tab_Base[Mês],H15,Tab_Base[Tipo],"Entrada") -> 0 | K15: =SUMIFS(Tab_Base[Valor],Tab_Base[Ano],$D$5,Tab_Base[Mês],H15,Tab_Base[Tipo],"Saída") -> 0 | L15: =J15-K15 -> 0
B16: 9 | C16: =IFERROR(DATE($D$5,$A$2,B16),"-") -> 45605 | D16: =SUMIFS(Tab_Base[Valor],Tab_Base[Data],DATE($D$5,$A$2,B16),Tab_Base[Tipo],"Entrada") -> 0 | E16: =SUMIFS(Tab_Base[Valor],Tab_Base[Data],DATE($D$5,$A$2,B16),Tab_Base[Tipo],"Saída") -> 2.15 | F16: =D16-E16 -> -2.15 | H16: 5 | I16: Maio | J16: =SUMIFS(Tab_Base[Valor],Tab_Base[Ano],$D$5,Tab_Base[Mês],H16,Tab_Base[Tipo],"Entrada") -> 0 | K16: =SUMIFS(Tab_Base[Valor],Tab_Base[Ano],$D$5,Tab_Base[Mês],H16,Tab_Base[Tipo],"Saída") -> 0 | L16: =J16-K16 -> 0
B17: 10 | C17: =IFERROR(DATE($D$5,$A$2,B17),"-") -> 45606 | D17: =SUMIFS(Tab_Base[Valor],Tab_Base[Data],DATE($D$5,$A$2,B17),Tab_Base[Tipo],"Entrada") -> 0 | E17: =SUMIFS(Tab_Base[Valor],Tab_Base[Data],DATE($D$5,$A$2,B17),Tab_Base[Tipo],"Saída") -> 0 | F17: =D17-E17 -> 0 | H17: 6 | I17: Junho | J17: =SUMIFS(Tab_Base[Valor],Tab_Base[Ano],$D$5,Tab_Base[Mês],H17,Tab_Base[Tipo],"Entrada") -> 0 | K17: =SUMIFS(Tab_Base[Valor],Tab_Base[Ano],$D$5,Tab_Base[Mês],H17,Tab_Base[Tipo],"Saída") -> 0 | L17: =J17-K17 -> 0
B18: 11 | C18: =IFERROR(DATE($D$5,$A$2,B18),"-") -> 45607 | D18: =SUMIFS(Tab_Base[Valor],Tab_Base[Data],DATE($D$5,$A$2,B18),Tab_Base[Tipo],"Entrada") -> 0 | E18: =SUMIFS(Tab_Base[Valor],Tab_Base[Data],DATE($D$5,$A$2,B18),Tab_Base[Tipo],"Saída") -> 0 | F18: =D18-E18 -> 0 | H18: 7 | I18: Julho | J18: =SUMIFS(Tab_Base[Valor],Tab_Base[Ano],$D$5,Tab_Base[Mês],H18,Tab_Base[Tipo],"Entrada") -> 0 | K18: =SUMIFS(Tab_Base[Valor],Tab_Base[Ano],$D$5,Tab_Base[Mês],H18,Tab_Base[Tipo],"Saída") -> 0 | L18: =J18-K18 -> 0
B19: 12 | C19: =IFERROR(DATE($D$5,$A$2,B19),"-") -> 45608 | D19: =SUMIFS(Tab_Base[Valor],Tab_Base[Data],DATE($D$5,$A$2,B19),Tab_Base[Tipo],"Entrada") -> 0 | E19: =SUMIFS(Tab_Base[Valor],Tab_Base[Data],DATE($D$5,$A$2,B19),Tab_Base[Tipo],"Saída") -> 0 | F19: =D19-E19 -> 0 | H19: 8 | I19: Agosto | J19: =SUMIFS(Tab_Base[Valor],Tab_Base[Ano],$D$5,Tab_Base[Mês],H19,Tab_Base[Tipo],"Entrada") -> 0 | K19: =SUMIFS(Tab_Base[Valor],Tab_Base[Ano],$D$5,Tab_Base[Mês],H19,Tab_Base[Tipo],"Saída") -> 0 | L19: =J19-K19 -> 0
B20: 13 | C20: =IFERROR(DATE($D$5,$A$2,B20),"-") -> 45609 | D20: =SUMIFS(Tab_Base[Valor],Tab_Base[Data],DATE($D$5,$A$2,B20),Tab_Base[Tipo],"Entrada") -> 0 | E20: =SUMIFS(Tab_Base[Valor],Tab_Base[Data],DATE($D$5,$A$2,B20),Tab_Base[Tipo],"Saída") -> 0 | F20: =D20-E20 -> 0 | H20: 9 | I20: Setembro | J20: =SUMIFS(Tab_Base[Valor],Tab_Base[Ano],$D$5,Tab_Base[Mês],H20,Tab_Base[Tipo],"Entrada") -> 0 | K20: =SUMIFS(Tab_Base[Valor],Tab_Base[Ano],$D$5,Tab_Base[Mês],H20,Tab_Base[Tipo],"Saída") -> 0 | L20: =J20-K20 -> 0
B21: 14 | C21: =IFERROR(DATE($D$5,$A$2,B21),"-") -> 45610 | D21: =SUMIFS(Tab_Base[Valor],Tab_Base[Data],DATE($D$5,$A$2,B21),Tab_Base[Tipo],"Entrada") -> 0 | E21: =SUMIFS(Tab_Base[Valor],Tab_Base[Data],DATE($D$5,$A$2,B21),Tab_Base[Tipo],"Saída") -> 0 | F21: =D21-E21 -> 0 | H21: 10 | I21: Outubro | J21: =SUMIFS(Tab_Base[Valor],Tab_Base[Ano],$D$5,Tab_Base[Mês],H21,Tab_Base[Tipo],"Entrada") -> 2650.49 | K21: =SUMIFS(Tab_Base[Valor],Tab_Base[Ano],$D$5,Tab_Base[Mês],H21,Tab_Base[Tipo],"Saída") -> 2648.4 | L21: =J21-K21 -> 2.09
B22: 15 | C22: =IFERROR(DATE($D$5,$A$2,B22),"-") -> 45611 | D22: =SUMIFS(Tab_Base[Valor],Tab_Base[Data],DATE($D$5,$A$2,B22),Tab_Base[Tipo],"Entrada") -> 0 | E22: =SUMIFS(Tab_Base[Valor],Tab_Base[Data],DATE($D$5,$A$2,B22),Tab_Base[Tipo],"Saída") -> 0 | F22: =D22-E22 -> 0 | H22: 11 | I22: Novembro | J22: =SUMIFS(Tab_Base[Valor],Tab_Base[Ano],$D$5,Tab_Base[Mês],H22,Tab_Base[Tipo],"Entrada") -> 2346 | K22: =SUMIFS(Tab_Base[Valor],Tab_Base[Ano],$D$5,Tab_Base[Mês],H22,Tab_Base[Tipo],"Saída") -> 2277.28 | L22: =J22-K22 -> 68.72
B23: 16 | C23: =IFERROR(DATE($D$5,$A$2,B23),"-") -> 45612 | D23: =SUMIFS(Tab_Base[Valor],Tab_Base[Data],DATE($D$5,$A$2,B23),Tab_Base[Tipo],"Entrada") -> 0 | E23: =SUMIFS(Tab_Base[Valor],Tab_Base[Data],DATE($D$5,$A$2,B23),Tab_Base[Tipo],"Saída") -> 0 | F23: =D23-E23 -> 0 | H23: 12 | I23: Dezembro | J23: =SUMIFS(Tab_Base[Valor],Tab_Base[Ano],$D$5,Tab_Base[Mês],H23,Tab_Base[Tipo],"Entrada") -> 0 | K23: =SUMIFS(Tab_Base[Valor],Tab_Base[Ano],$D$5,Tab_Base[Mês],H23,Tab_Base[Tipo],"Saída") -> 0 | L23: =J23-K23 -> 0
B24: 17 | C24: =IFERROR(DATE($D$5,$A$2,B24),"-") -> 45613 | D24: =SUMIFS(Tab_Base[Valor],Tab_Base[Data],DATE($D$5,$A$2,B24),Tab_Base[Tipo],"Entrada") -> 0 | E24: =SUMIFS(Tab_Base[Valor],Tab_Base[Data],DATE($D$5,$A$2,B24),Tab_Base[Tipo],"Saída") -> 0 | F24: =D24-E24 -> 0
B25: 18 | C25: =IFERROR(DATE($D$5,$A$2,B25),"-") -> 45614 | D25: =SUMIFS(Tab_Base[Valor],Tab_Base[Data],DATE($D$5,$A$2,B25),Tab_Base[Tipo],"Entrada") -> 0 | E25: =SUMIFS(Tab_Base[Valor],Tab_Base[Data],DATE($D$5,$A$2,B25),Tab_Base[Tipo],"Saída") -> 0 | F25: =D25-E25 -> 0 | I25: ="Total "&D5 -> Total 2024 | J25: =SUM(J12:J23) -> 4996.49 | K25: =SUM(K12:K23) -> 4925.68 | L25: =J25-K25 -> 70.81
B26: 19 | C26: =IFERROR(DATE($D$5,$A$2,B26),"-") -> 45615 | D26: =SUMIFS(Tab_Base[Valor],Tab_Base[Data],DATE($D$5,$A$2,B26),Tab_Base[Tipo],"Entrada") -> 0 | E26: =SUMIFS(Tab_Base[Valor],Tab_Base[Data],DATE($D$5,$A$2,B26),Tab_Base[Tipo],"Saída") -> 0 | F26: =D26-E26 -> 0
B27: 20 | C27: =IFERROR(DATE($D$5,$A$2,B27),"-") -> 45616 | D27: =SUMIFS(Tab_Base[Valor],Tab_Base[Data],DATE($D$5,$A$2,B27),Tab_Base[Tipo],"Entrada") -> 0 | E27: =SUMIFS(Tab_Base[Valor],Tab_Base[Data],DATE($D$5,$A$2,B27),Tab_Base[Tipo],"Saída") -> 0 | F27: =D27-E27 -> 0
B28: 21 | C28: =IFERROR(DATE($D$5,$A$2,B28),"-") -> 45617 | D28: =SUMIFS(Tab_Base[Valor],Tab_Base[Data],DATE($D$5,$A$2,B28),Tab_Base[Tipo],"Entrada") -> 0 | E28: =SUMIFS(Tab_Base[Valor],Tab_Base[Data],DATE($D$5,$A$2,B28),Tab_Base[Tipo],"Saída") -> 0 | F28: =D28-E28 -> 0
B29: 22 | C29: =IFERROR(DATE($D$5,$A$2,B29),"-") -> 45618 | D29: =SUMIFS(Tab_Base[Valor],Tab_Base[Data],DATE($D$5,$A$2,B29),Tab_Base[Tipo],"Entrada") -> 0 | E29: =SUMIFS(Tab_Base[Valor],Tab_Base[Data],DATE($D$5,$A$2,B29),Tab_Base[Tipo],"Saída") -> 0 | F29: =D29-E29 -> 0
B30: 23 | C30: =IFERROR(DATE($D$5,$A$2,B30),"-") -> 45619 | D30: =SUMIFS(Tab_Base[Valor],Tab_Base[Data],DATE($D$5,$A$2,B30),Tab_Base[Tipo],"Entrada") -> 0 | E30: =SUMIFS(Tab_Base[Valor],Tab_Base[Data],DATE($D$5,$A$2,B30),Tab_Base[Tipo],"Saída") -> 0 | F30: =D30-E30 -> 0
B31: 24 | C31: =IFERROR(DATE($D$5,$A$2,B31),"-") -> 45620 | D31: =SUMIFS(Tab_Base[Valor],Tab_Base[Data],DATE($D$5,$A$2,B31),Tab_Base[Tipo],"Entrada") -> 0 | E31: =SUMIFS(Tab_Base[Valor],Tab_Base[Data],DATE($D$5,$A$2,B31),Tab_Base[Tipo],"Saída") -> 0 | F31: =D31-E31 -> 0
B32: 25 | C32: =IFERROR(DATE($D$5,$A$2,B32),"-") -> 45621 | D32: =SUMIFS(Tab_Base[Valor],Tab_Base[Data],DATE($D$5,$A$2,B32),Tab_Base[Tipo],"Entrada") -> 0 | E32: =SUMIFS(Tab_Base[Valor],Tab_Base[Data],DATE($D$5,$A$2,B32),Tab_Base[Tipo],"Saída") -> 0 | F32: =D32-E32 -> 0
B33: 26 | C33: =IFERROR(DATE($D$5,$A$2,B33),"-") -> 45622 | D33: =SUMIFS(Tab_Base[Valor],Tab_Base[Data],DATE($D$5,$A$2,B33),Tab_Base[Tipo],"Entrada") -> 0 | E33: =SUMIFS(Tab_Base[Valor],Tab_Base[Data],DATE($D$5,$A$2,B33),Tab_Base[Tipo],"Saída") -> 0 | F33: =D33-E33 -> 0
B34: 27 | C34: =IFERROR(DATE($D$5,$A$2,B34),"-") -> 45623 | D34: =SUMIFS(Tab_Base[Valor],Tab_Base[Data],DATE($D$5,$A$2,B34),Tab_Base[Tipo],"Entrada") -> 0 | E34: =SUMIFS(Tab_Base[Valor],Tab_Base[Data],DATE($D$5,$A$2,B34),Tab_Base[Tipo],"Saída") -> 0 | F34: =D34-E34 -> 0
B35: 28 | C35: =IFERROR(DATE($D$5,$A$2,B35),"-") -> 45624 | D35: =SUMIFS(Tab_Base[Valor],Tab_Base[Data],DATE($D$5,$A$2,B35),Tab_Base[Tipo],"Entrada") -> 0 | E35: =SUMIFS(Tab_Base[Valor],Tab_Base[Data],DATE($D$5,$A$2,B35),Tab_Base[Tipo],"Saída") -> 0 | F35: =D35-E35 -> 0
B36: =IFERROR(IF(B35=$D$2,"-",B35+1),"-") -> 29 | C36: =IFERROR(DATE($D$5,$A$2,B36),"-") -> 45625 | D36: =IF(B36="-","-",SUMIFS(Tab_Base[Valor],Tab_Base[Data],DATE($D$5,$A$2,B36),Tab_Base[Tipo],"Entrada")) -> 0 | E36: =IF(B36="-","-",SUMIFS(Tab_Base[Valor],Tab_Base[Data],DATE($D$5,$A$2,B36),Tab_Base[Tipo],"Saída")) -> 0 | F36: =IFERROR(D36-E36,"-") -> 0
B37: =IFERROR(IF(B36=$D$2,"-",B36+1),"-") -> 30 | C37: =IFERROR(DATE($D$5,$A$2,B37),"-") -> 45626 | D37: =IF(B37="-","-",SUMIFS(Tab_Base[Valor],Tab_Base[Data],DATE($D$5,$A$2,B37),Tab_Base[Tipo],"Entrada")) -> 0 | E37: =IF(B37="-","-",SUMIFS(Tab_Base[Valor],Tab_Base[Data],DATE($D$5,$A$2,B37),Tab_Base[Tipo],"Saída")) -> 0 | F37: =IFERROR(D37-E37,"-") -> 0
B38: =IFERROR(IF(B37=$D$2,"-",B37+1),"-") -> - | C38: =IFERROR(DATE($D$5,$A$2,B38),"-") -> - | D38: =IF(B38="-","-",SUMIFS(Tab_Base[Valor],Tab_Base[Data],DATE($D$5,$A$2,B38),Tab_Base[Tipo],"Entrada")) -> - | E38: =IF(B38="-","-",SUMIFS(Tab_Base[Valor],Tab_Base[Data],DATE($D$5,$A$2,B38),Tab_Base[Tipo],"Saída")) -> - | F38: =IFERROR(D38-E38,"-") -> -
C40: Total Mês | D40: =SUM(D8:D38) -> 2346 | E40: =SUM(E8:E38) -> 2277.28 | F40: =D40-E40 -> 68.72

Sheet Auxiliar
B1: Total | C1: =SUM(tb_saidas[Janeiro]) -> 0 | D1: =SUM(tb_saidas[Fevereiro]) -> 0 | E1: =SUM(tb_saidas[Março]) -> 0 | F1: =SUM(tb_saidas[Abril]) -> 0 | G1: =SUM(tb_saidas[Maio]) -> 0 | H1: =SUM(tb_saidas[Junho]) -> 0 | I1: =SUM(tb_saidas[Julho]) -> 0 | J1: =SUM(tb_saidas[Agosto]) -> 0 | K1: =SUM(tb_saidas[Setembro]) -> 0 | L1: =SUM(tb_saidas[Outubro]) -> 2545.62 | M1: =SUM(tb_saidas[Novembro]) -> 2075.13 | N1: =SUM(tb_saidas[Dezembro]) -> 0 | O1: =SUM(tb_saidas[Total]) -> 4620.75 | P1: =SUM(tb_saidas[Total Per]) -> 4925.68 | R1: Total | S1: =SUM(tb_entradas[Janeiro]) -> 0 | T1: =SUM(tb_entradas[Fevereiro]) -> 0 | U1: =SUM(tb_entradas[Março]) -> 0 | V1: =SUM(tb_entradas[Abril]) -> 0 | W1: =SUM(tb_entradas[Maio]) -> 0 | X1: =SUM(tb_entradas[Junho]) -> 0 | Y1: =SUM(tb_entradas[Julho]) -> 0 | Z1: =SUM(tb_entradas[Agosto]) -> 0 | AA1: =SUM(tb_entradas[Setembro]) -> 0 | AB1: =SUM(tb_entradas[Outubro]) -> 2296 | AC1: =SUM(tb_entradas[Novembro]) -> 2346 | AD1: =SUM(tb_entradas[Dezembro]) -> 0 | AE1: =SUM(tb_entradas[Total]) -> 4642 | AF1: =SUM(tb_entradas[Total Per]) -> 4642
P2: =DashBoard!J11 -> 45566 | AF2: =DashBoard!J11 -> 45566
B3: =DashBoard!C3 -> 2024 | C3: 1 | D3: 2 | E3: 3 | F3: 4 | G3: 5 | H3: 6 | I3: 7 | J3: 8 | K3: 9 | L3: 10 | M3: 11 | N3: 12 | P3: =DashBoard!M11 -> 45657 | R3: =DashBoard!C3 -> 2024 | S3: 1 | T3: 2 | U3: 3 | V3: 4 | W3: 5 | X3: 6 | Y3: 7 | Z3: 8 | AA3: 9 | AB3: 10 | AC3: 11 | AD3: 12 | AF3: =DashBoard!M11 -> 45657
B4: Saídas | C4: Janeiro | D4: Fevereiro | E4: Março | F4: Abril | G4: Maio | H4: Junho | I4: Julho | J4: Agosto | K4: Setembro | L4: Outubro | M4: Novembro | N4: Dezembro | O4: Total | P4: Total Per | R4: Entradas | S4: Janeiro | T4: Fevereiro | U4: Março | V4: Abril | W4: Maio | X4: Junho | Y4: Julho | Z4: Agosto | AA4: Setembro | AB4: Outubro | AC4: Novembro | AD4: Dezembro | AE4: Total | AF4: Total Per | AH4: Saldo Inicial da Conta | AI4: 0.07 | AK4: Descrição (opcional)
B5: Caixinha Faculdade | C5: =SUMIFS(Tab_Base[[Valor]:[Valor]],Tab_Base[[Categoria]:[Categoria]],$B2,Tab_Base[[Mês]:[Mês]],C$3,Tab_Base[[Ano]:[Ano]],$B$3,Tab_Base[[Tipo]:[Tipo]],"Saída") -> 0 | D5: =SUMIFS(Tab_Base[[Valor]:[Valor]],Tab_Base[[Categoria]:[Categoria]],$B2,Tab_Base[[Mês]:[Mês]],D$3,Tab_Base[[Ano]:[Ano]],$B$3,Tab_Base[[Tipo]:[Tipo]],"Saída") -> 0 | E5: =SUMIFS(Tab_Base[[Valor]:[Valor]],Tab_Base[[Categoria]:[Categoria]],$B2,Tab_Base[[Mês]:[Mês]],E$3,Tab_Base[[Ano]:[Ano]],$B$3,Tab_Base[[Tipo]:[Tipo]],"Saída") -> 0 | F5: =SUMIFS(Tab_Base[[Valor]:[Valor]],Tab_Base[[Categoria]:[Categoria]],$B2,Tab_Base[[Mês]:[Mês]],F$3,Tab_Base[[Ano]:[Ano]],$B$3,Tab_Base[[Tipo]:[Tipo]],"Saída") -> 0 | G5: =SUMIFS(Tab_Base[[Valor]:[Valor]],Tab_Base[[Categoria]:[Categoria]],$B2,Tab_Base[[Mês]:[Mês]],G$3,Tab_Base[[Ano]:[Ano]],$B$3,Tab_Base[[Tipo]:[Tipo]],"Saída") -> 0 | H5: =SUMIFS(Tab_Base[[Valor]:[Valor]],Tab_Base[[Categoria]:[Categoria]],$B2,Tab_Base[[Mês]:[Mês]],H$3,Tab_Base[[Ano]:[Ano]],$B$3,Tab_Base[[Tipo]:[Tipo]],"Saída") -> 0 | I5: =SUMIFS(Tab_Base[[Valor]:[Valor]],Tab_Base[[Categoria]:[Categoria]],$B2,Tab_Base[[Mês]:[Mês]],I$3,Tab_Base[[Ano]:[Ano]],$B$3,Tab_Base[[Tipo]:[Tipo]],"Saída") -> 0 | J5: =SUMIFS(Tab_Base[[Valor]:[Valor]],Tab_Base[[Categoria]:[Categoria]],$B2,Tab_Base[[Mês]:[Mês]],J$3,Tab_Base[[Ano]:[Ano]],$B$3,Tab_Base[[Tipo]:[Tipo]],"Saída") -> 0 | ... N5: =SUMIFS(Tab_Base[[Valor]:[Valor]],Tab_Base[[Categoria]:[Categoria]],$B2,Tab_Base[[Mês]:[Mês]],N$3,Tab_Base[[Ano]:[Ano]],$B$3,Tab_Base[[Tipo]:[Tipo]],"Saída") -> 0 | O5: =SUM(tb_saidas[[#This Row],[Janeiro]:[Dezembro]]) -> 0 | P5: =SUMIFS(Tab_Base[Valor],Tab_Base[Categoria],tb_saidas[[#This Row],[Saídas]],Tab_Base[Data],">="&$P$2,Tab_Base[Data],"<="&$P$3,Tab_Base[Tipo],"Saída") -> 50 | R5: Salário | S5: =SUMIFS(Tab_Base[[Valor]:[Valor]],Tab_Base[[Categoria]:[Categoria]],$R5,Tab_Base[[Mês]:[Mês]],S$3,Tab_Base[[Ano]:[Ano]],$R$3,Tab_Base[[Tipo]:[Tipo]],"Entrada") -> 0 | T5: =SUMIFS(Tab_Base[[Valor]:[Valor]],Tab_Base[[Categoria]:[Categoria]],$R5,Tab_Base[[Mês]:[Mês]],T$3,Tab_Base[[Ano]:[Ano]],$R$3,Tab_Base[[Tipo]:[Tipo]],"Entrada") -> 0 | U5: =SUMIFS(Tab_Base[[Valor]:[Valor]],Tab_Base[[Categoria]:[Categoria]],$R5,Tab_Base[[Mês]:[Mês]],U$3,Tab_Base[[Ano]:[Ano]],$R$3,Tab_Base[[Tipo]:[Tipo]],"Entrada") -> 0 | V5: =SUMIFS(Tab_Base[[Valor]:[Valor]],Tab_Base[[Categoria]:[Categoria]],$R5,Tab_Base[[Mês]:[Mês]],V$3,Tab_Base[[Ano]:[Ano]],$R$3,Tab_Base[[Tipo]:[Tipo]],"Entrada") -> 0 | W5: =SUMIFS(Tab_Base[[Valor]:[Valor]],Tab_Base[[Categoria]:[Categoria]],$R5,Tab_Base[[Mês]:[Mês]],W$3,Tab_Base[[Ano]:[Ano]],$R$3,Tab_Base[[Tipo]:[Tipo]],"Entrada") -> 0 | X5: =SUMIFS(Tab_Base[[Valor]:[Valor]],Tab_Base[[Categoria]:[Categoria]],$R5,Tab_Base[[Mês]:[Mês]],X$3,Tab_Base[[Ano]:[Ano]],$R$3,Tab_Base[[Tipo]:[Tipo]],"Entrada") -> 0 | Y5: =SUMIFS(Tab_Base[[Valor]:[Valor]],Tab_Base[[Categoria]:[Categoria]],$R5,Tab_Base[[Mês]:[Mês]],Y$3,Tab_Base[[Ano]:[Ano]],$R$3,Tab_Base[[Tipo]:[Tipo]],"Entrada") -> 0 | Z5: =SUMIFS(Tab_Base[[Valor]:[Valor]],Tab_Base[[Categoria]:[Categoria]],$R5,Tab_Base[[Mês]:[Mês]],Z$3,Tab_Base[[Ano]:[Ano]],$R$3,Tab_Base[[Tipo]:[Tipo]],"Entrada") -> 0 | ... AD5: =SUMIFS(Tab_Base[[Valor]:[Valor]],Tab_Base[[Categoria]:[Categoria]],$R5,Tab_Base[[Mês]:[Mês]],AD$3,Tab_Base[[Ano]:[Ano]],$R$3,Tab_Base[[Tipo]:[Tipo]],"Entrada") -> 0 | AE5: =SUM(tb_entradas[[#This Row],[Janeiro]:[Dezembro]]) -> 4592 | AF5: =SUMIFS(Tab_Base[Valor],Tab_Base[Categoria],tb_entradas[[#This Row],[Entradas]],Tab_Base[Data],">="&$AF$2,Tab_Base[Data],"<="&$AF$3,Tab_Base[Tipo],"Entrada") -> 4592
B6: Fatura Cartão | C6: =SUMIFS(Tab_Base[[Valor]:[Valor]],Tab_Base[[Categoria]:[Categoria]],#REF!,Tab_Base[[Mês]:[Mês]],C$3,Tab_Base[[Ano]:[Ano]],$B$3,Tab_Base[[Tipo]:[Tipo]],"Saída") -> 0 | D6: =SUMIFS(Tab_Base[[Valor]:[Valor]],Tab_Base[[Categoria]:[Categoria]],#REF!,Tab_Base[[Mês]:[Mês]],D$3,Tab_Base[[Ano]:[Ano]],$B$3,Tab_Base[[Tipo]:[Tipo]],"Saída") -> 0 | E6: =SUMIFS(Tab_Base[[Valor]:[Valor]],Tab_Base[[Categoria]:[Categoria]],#REF!,Tab_Base[[Mês]:[Mês]],E$3,Tab_Base[[Ano]:[Ano]],$B$3,Tab_Base[[Tipo]:[Tipo]],"Saída") -> 0 | F6: =SUMIFS(Tab_Base[[Valor]:[Valor]],Tab_Base[[Categoria]:[Categoria]],#REF!,Tab_Base[[Mês]:[Mês]],F$3,Tab_Base[[Ano]:[Ano]],$B$3,Tab_Base[[Tipo]:[Tipo]],"Saída") -> 0 | G6: =SUMIFS(Tab_Base[[Valor]:[Valor]],Tab_Base[[Categoria]:[Categoria]],#REF!,Tab_Base[[Mês]:[Mês]],G$3,Tab_Base[[Ano]:[Ano]],$B$3,Tab_Base[[Tipo]:[Tipo]],"Saída") -> 0 | H6: =SUMIFS(Tab_Base[[Valor]:[Valor]],Tab_Base[[Categoria]:[Categoria]],#REF!,Tab_Base[[Mês]:[Mês]],H$3,Tab_Base[[Ano]:[Ano]],$B$3,Tab_Base[[Tipo]:[Tipo]],"Saída") -> 0 | I6: =SUMIFS(Tab_Base[[Valor]:[Valor]],Tab_Base[[Categoria]:[Categoria]],#REF!,Tab_Base[[Mês]:[Mês]],I$3,Tab_Base[[Ano]:[Ano]],$B$3,Tab_Base[[Tipo]:[Tipo]],"Saída") -> 0 | J6: =SUMIFS(Tab_Base[[Valor]:[Valor]],Tab_Base[[Categoria]:[Categoria]],#REF!,Tab_Base[[Mês]:[Mês]],J$3,Tab_Base[[Ano]:[Ano]],$B$3,Tab_Base[[Tipo]:[Tipo]],"Saída") -> 0 | ... N6: =SUMIFS(Tab_Base[[Valor]:[Valor]],Tab_Base[[Categoria]:[Categoria]],#REF!,Tab_Base[[Mês]:[Mês]],N$3,Tab_Base[[Ano]:[Ano]],$B$3,Tab_Base[[Tipo]:[Tipo]],"Saída") -> 0 | O6: =SUM(tb_saidas[[#This Row],[Janeiro]:[Dezembro]]) -> 0 | P6: =SUMIFS(Tab_Base[Valor],Tab_Base[Categoria],tb_saidas[[#This Row],[Saídas]],Tab_Base[Data],">="&$P$2,Tab_Base[Data],"<="&$P$3,Tab_Base[Tipo],"Saída") -> 3132.95 | R6: Serviço Extra | S6: =SUMIFS(Tab_Base[[Valor]:[Valor]],Tab_Base[[Categoria]:[Categoria]],$R6,Tab_Base[[Mês]:[Mês]],S$3,Tab_Base[[Ano]:[Ano]],$R$3,Tab_Base[[Tipo]:[Tipo]],"Entrada") -> 0 | T6: =SUMIFS(Tab_Base[[Valor]:[Valor]],Tab_Base[[Categoria]:[Categoria]],$R6,Tab_Base[[Mês]:[Mês]],T$3,Tab_Base[[Ano]:[Ano]],$R$3,Tab_Base[[Tipo]:[Tipo]],"Entrada") -> 0 | U6: =SUMIFS(Tab_Base[[Valor]:[Valor]],Tab_Base[[Categoria]:[Categoria]],$R6,Tab_Base[[Mês]:[Mês]],U$3,Tab_Base[[Ano]:[Ano]],$R$3,Tab_Base[[Tipo]:[Tipo]],"Entrada") -> 0 | V6: =SUMIFS(Tab_Base[[Valor]:[Valor]],Tab_Base[[Categoria]:[Categoria]],$R6,Tab_Base[[Mês]:[Mês]],V$3,Tab_Base[[Ano]:[Ano]],$R$3,Tab_Base[[Tipo]:[Tipo]],"Entrada") -> 0 | W6: =SUMIFS(Tab_Base[[Valor]:[Valor]],Tab_Base[[Categoria]:[Categoria]],$R6,Tab_Base[[Mês]:[Mês]],W$3,Tab_Base[[Ano]:[Ano]],$R$3,Tab_Base[[Tipo]:[Tipo]],"Entrada") -> 0 | X6: =SUMIFS(Tab_Base[[Valor]:[Valor]],Tab_Base[[Categoria]:[Categoria]],$R6,Tab_Base[[Mês]:[Mês]],X$3,Tab_Base[[Ano]:[Ano]],$R$3,Tab_Base[[Tipo]:[Tipo]],"Entrada") -> 0 | Y6: =SUMIFS(Tab_Base[[Valor]:[Valor]],Tab_Base[[Categoria]:[Categoria]],$R6,Tab_Base[[Mês]:[Mês]],Y$3,Tab_Base[[Ano]:[Ano]],$R$3,Tab_Base[[Tipo]:[Tipo]],"Entrada") -> 0 | Z6: =SUMIFS(Tab_Base[[Valor]:[Valor]],Tab_Base[[Categoria]:[Categoria]],$R6,Tab_Base[[Mês]:[Mês]],Z$3,Tab_Base[[Ano]:[Ano]],$R$3,Tab_Base[[Tipo]:[Tipo]],"Entrada") -> 0 | ... AD6: =SUMIFS(Tab_Base[[Valor]:[Valor]],Tab_Base[[Categoria]:[Categoria]],$R6,Tab_Base[[Mês]:[Mês]],AD$3,Tab_Base[[Ano]:[Ano]],$R$3,Tab_Base[[Tipo]:[Tipo]],"Entrada") -> 0 | AE6: =SUM(tb_entradas[[#This Row],[Janeiro]:[Dezembro]]) -> 50 | AF6: =SUMIFS(Tab_Base[Valor],Tab_Base[Categoria],tb_entradas[[#This Row],[Entradas]],Tab_Base[Data],">="&$AF$2,Tab_Base[Data],"<="&$AF$3,Tab_Base[Tipo],"Entrada") -> 50
B7: Internet | C7: =SUMIFS(Tab_Base[[Valor]:[Valor]],Tab_Base[[Categoria]:[Categoria]],$B7,Tab_Base[[Mês]:[Mês]],C$3,Tab_Base[[Ano]:[Ano]],$B$3,Tab_Base[[Tipo]:[Tipo]],"Saída") -> 0 | D7: =SUMIFS(Tab_Base[[Valor]:[Valor]],Tab_Base[[Categoria]:[Categoria]],$B7,Tab_Base[[Mês]:[Mês]],D$3,Tab_Base[[Ano]:[Ano]],$B$3,Tab_Base[[Tipo]:[Tipo]],"Saída") -> 0 | E7: =SUMIFS(Tab_Base[[Valor]:[Valor]],Tab_Base[[Categoria]:[Categoria]],$B7,Tab_Base[[Mês]:[Mês]],E$3,Tab_Base[[Ano]:[Ano]],$B$3,Tab_Base[[Tipo]:[Tipo]],"Saída") -> 0 | F7: =SUMIFS(Tab_Base[[Valor]:[Valor]],Tab_Base[[Categoria]:[Categoria]],$B7,Tab_Base[[Mês]:[Mês]],F$3,Tab_Base[[Ano]:[Ano]],$B$3,Tab_Base[[Tipo]:[Tipo]],"Saída") -> 0 | G7: =SUMIFS(Tab_Base[[Valor]:[Valor]],Tab_Base[[Categoria]:[Categoria]],$B7,Tab_Base[[Mês]:[Mês]],G$3,Tab_Base[[Ano]:[Ano]],$B$3,Tab_Base[[Tipo]:[Tipo]],"Saída") -> 0 | H7: =SUMIFS(Tab_Base[[Valor]:[Valor]],Tab_Base[[Categoria]:[Categoria]],$B7,Tab_Base[[Mês]:[Mês]],H$3,Tab_Base[[Ano]:[Ano]],$B$3,Tab_Base[[Tipo]:[Tipo]],"Saída") -> 0 | I7: =SUMIFS(Tab_Base[[Valor]:[Valor]],Tab_Base[[Categoria]:[Categoria]],$B7,Tab_Base[[Mês]:[Mês]],I$3,Tab_Base[[Ano]:[Ano]],$B$3,Tab_Base[[Tipo]:[Tipo]],"Saída") -> 0 | J7: =SUMIFS(Tab_Base[[Valor]:[Valor]],Tab_Base[[Categoria]:[Categoria]],$B7,Tab_Base[[Mês]:[Mês]],J$3,Tab_Base[[Ano]:[Ano]],$B$3,Tab_Base[[Tipo]:[Tipo]],"Saída") -> 0 | ... N7: =SUMIFS(Tab_Base[[Valor]:[Valor]],Tab_Base[[Categoria]:[Categoria]],$B7,Tab_Base[[Mês]:[Mês]],N$3,Tab_Base[[Ano]:[Ano]],$B$3,Tab_Base[[Tipo]:[Tipo]],"Saída") -> 0 | O7: =SUM(tb_saidas[[#This Row],[Janeiro]:[Dezembro]]) -> 199.8 | P7: =SUMIFS(Tab_Base[Valor],Tab_Base[Categoria],tb_saidas[[#This Row],[Saídas]],Tab_Base[Data],">="&$P$2,Tab_Base[Data],"<="&$P$3,Tab_Base[Tipo],"Saída") -> 199.8 | S7: =SUMIFS(Tab_Base[[Valor]:[Valor]],Tab_Base[[Categoria]:[Categoria]],$R7,Tab_Base[[Mês]:[Mês]],S$3,Tab_Base[[Ano]:[Ano]],$R$3,Tab_Base[[Tipo]:[Tipo]],"Entrada") -> 0 | T7: =SUMIFS(Tab_Base[[Valor]:[Valor]],Tab_Base[[Categoria]:[Categoria]],$R7,Tab_Base[[Mês]:[Mês]],T$3,Tab_Base[[Ano]:[Ano]],$R$3,Tab_Base[[Tipo]:[Tipo]],"Entrada") -> 0 | U7: =SUMIFS(Tab_Base[[Valor]:[Valor]],Tab_Base[[Categoria]:[Categoria]],$R7,Tab_Base[[Mês]:[Mês]],U$3,Tab_Base[[Ano]:[Ano]],$R$3,Tab_Base[[Tipo]:[Tipo]],"Entrada") -> 0 | V7: =SUMIFS(Tab_Base[[Valor]:[Valor]],Tab_Base[[Categoria]:[Categoria]],$R7,Tab_Base[[Mês]:[Mês]],V$3,Tab_Base[[Ano]:[Ano]],$R$3,Tab_Base[[Tipo]:[Tipo]],"Entrada") -> 0 | W7: =SUMIFS(Tab_Base[[Valor]:[Valor]],Tab_Base[[Categoria]:[Categoria]],$R7,Tab_Base[[Mês]:[Mês]],W$3,Tab_Base[[Ano]:[Ano]],$R$3,Tab_Base[[Tipo]:[Tipo]],"Entrada") -> 0 | X7: =SUMIFS(Tab_Base[[Valor]:[Valor]],Tab_Base[[Categoria]:[Categoria]],$R7,Tab_Base[[Mês]:[Mês]],X$3,Tab_Base[[Ano]:[Ano]],$R$3,Tab_Base[[Tipo]:[Tipo]],"Entrada") -> 0 | Y7: =SUMIFS(Tab_Base[[Valor]:[Valor]],Tab_Base[[Categoria]:[Categoria]],$R7,Tab_Base[[Mês]:[Mês]],Y$3,Tab_Base[[Ano]:[Ano]],$R$3,Tab_Base[[Tipo]:[Tipo]],"Entrada") -> 0 | Z7: =SUMIFS(Tab_Base[[Valor]:[Valor]],Tab_Base[[Categoria]:[Categoria]],$R7,Tab_Base[[Mês]:[Mês]],Z$3,Tab_Base[[Ano]:[Ano]],$R$3,Tab_Base[[Tipo]:[Tipo]],"Entrada") -> 0 | ... AD7: =SUMIFS(Tab_Base[[Valor]:[Valor]],Tab_Base[[Categoria]:[Categoria]],$R7,Tab_Base[[Mês]:[Mês]],AD$3,Tab_Base[[Ano]:[Ano]],$R$3,Tab_Base[[Tipo]:[Tipo]],"Entrada") -> 0 | AE7: =SUM(tb_entradas[[#This Row],[Janeiro]:[Dezembro]]) -> 0 | AF7: =SUMIFS(Tab_Base[Valor],Tab_Base[Categoria],tb_entradas[[#This Row],[Entradas]],Tab_Base[Data],">="&$AF$2,Tab_Base[Data],"<="&$AF$3,Tab_Base[Tipo],"Entrada") -> 0
B8: Investimento CDB | C8: =SUMIFS(Tab_Base[[Valor]:[Valor]],Tab_Base[[Categoria]:[Categoria]],$B5,Tab_Base[[Mês]:[Mês]],C$3,Tab_Base[[Ano]:[Ano]],$B$3,Tab_Base[[Tipo]:[Tipo]],"Saída") -> 0 | D8: =SUMIFS(Tab_Base[[Valor]:[Valor]],Tab_Base[[Categoria]:[Categoria]],$B5,Tab_Base[[Mês]:[Mês]],D$3,Tab_Base[[Ano]:[Ano]],$B$3,Tab_Base[[Tipo]:[Tipo]],"Saída") -> 0 | E8: =SUMIFS(Tab_Base[[Valor]:[Valor]],Tab_Base[[Categoria]:[Categoria]],$B5,Tab_Base[[Mês]:[Mês]],E$3,Tab_Base[[Ano]:[Ano]],$B$3,Tab_Base[[Tipo]:[Tipo]],"Saída") -> 0 | F8: =SUMIFS(Tab_Base[[Valor]:[Valor]],Tab_Base[[Categoria]:[Categoria]],$B5,Tab_Base[[Mês]:[Mês]],F$3,Tab_Base[[Ano]:[Ano]],$B$3,Tab_Base[[Tipo]:[Tipo]],"Saída") -> 0 | G8: =SUMIFS(Tab_Base[[Valor]:[Valor]],Tab_Base[[Categoria]:[Categoria]],$B5,Tab_Base[[Mês]:[Mês]],G$3,Tab_Base[[Ano]:[Ano]],$B$3,Tab_Base[[Tipo]:[Tipo]],"Saída") -> 0 | H8: =SUMIFS(Tab_Base[[Valor]:[Valor]],Tab_Base[[Categoria]:[Categoria]],$B5,Tab_Base[[Mês]:[Mês]],H$3,Tab_Base[[Ano]:[Ano]],$B$3,Tab_Base[[Tipo]:[Tipo]],"Saída") -> 0 | I8: =SUMIFS(Tab_Base[[Valor]:[Valor]],Tab_Base[[Categoria]:[Categoria]],$B5,Tab_Base[[Mês]:[Mês]],I$3,Tab_Base[[Ano]:[Ano]],$B$3,Tab_Base[[Tipo]:[Tipo]],"Saída") -> 0 | J8: =SUMIFS(Tab_Base[[Valor]:[Valor]],Tab_Base[[Categoria]:[Categoria]],$B5,Tab_Base[[Mês]:[Mês]],J$3,Tab_Base[[Ano]:[Ano]],$B$3,Tab_Base[[Tipo]:[Tipo]],"Saída") -> 0 | ... N8: =SUMIFS(Tab_Base[[Valor]:[Valor]],Tab_Base[[Categoria]:[Categoria]],$B5,Tab_Base[[Mês]:[Mês]],N$3,Tab_Base[[Ano]:[Ano]],$B$3,Tab_Base[[Tipo]:[Tipo]],"Saída") -> 0 | O8: =SUM(tb_saidas[[#This Row],[Janeiro]:[Dezembro]]) -> 50 | P8: =SUMIFS(Tab_Base[Valor],Tab_Base[Categoria],tb_saidas[[#This Row],[Saídas]],Tab_Base[Data],">="&$P$2,Tab_Base[Data],"<="&$P$3,Tab_Base[Tipo],"Saída") -> 330
B9: Juliana Bofi - Clínica Dentista | C9: =SUMIFS(Tab_Base[[Valor]:[Valor]],Tab_Base[[Categoria]:[Categoria]],$B6,Tab_Base[[Mês]:[Mês]],C$3,Tab_Base[[Ano]:[Ano]],$B$3,Tab_Base[[Tipo]:[Tipo]],"Saída") -> 0 | D9: =SUMIFS(Tab_Base[[Valor]:[Valor]],Tab_Base[[Categoria]:[Categoria]],$B6,Tab_Base[[Mês]:[Mês]],D$3,Tab_Base[[Ano]:[Ano]],$B$3,Tab_Base[[Tipo]:[Tipo]],"Saída") -> 0 | E9: =SUMIFS(Tab_Base[[Valor]:[Valor]],Tab_Base[[Categoria]:[Categoria]],$B6,Tab_Base[[Mês]:[Mês]],E$3,Tab_Base[[Ano]:[Ano]],$B$3,Tab_Base[[Tipo]:[Tipo]],"Saída") -> 0 | F9: =SUMIFS(Tab_Base[[Valor]:[Valor]],Tab_Base[[Categoria]:[Categoria]],$B6,Tab_Base[[Mês]:[Mês]],F$3,Tab_Base[[Ano]:[Ano]],$B$3,Tab_Base[[Tipo]:[Tipo]],"Saída") -> 0 | G9: =SUMIFS(Tab_Base[[Valor]:[Valor]],Tab_Base[[Categoria]:[Categoria]],$B6,Tab_Base[[Mês]:[Mês]],G$3,Tab_Base[[Ano]:[Ano]],$B$3,Tab_Base[[Tipo]:[Tipo]],"Saída") -> 0 | H9: =SUMIFS(Tab_Base[[Valor]:[Valor]],Tab_Base[[Categoria]:[Categoria]],$B6,Tab_Base[[Mês]:[Mês]],H$3,Tab_Base[[Ano]:[Ano]],$B$3,Tab_Base[[Tipo]:[Tipo]],"Saída") -> 0 | I9: =SUMIFS(Tab_Base[[Valor]:[Valor]],Tab_Base[[Categoria]:[Categoria]],$B6,Tab_Base[[Mês]:[Mês]],I$3,Tab_Base[[Ano]:[Ano]],$B$3,Tab_Base[[Tipo]:[Tipo]],"Saída") -> 0 | J9: =SUMIFS(Tab_Base[[Valor]:[Valor]],Tab_Base[[Categoria]:[Categoria]],$B6,Tab_Base[[Mês]:[Mês]],J$3,Tab_Base[[Ano]:[Ano]],$B$3,Tab_Base[[Tipo]:[Tipo]],"Saída") -> 0 | ... N9: =SUMIFS(Tab_Base[[Valor]:[Valor]],Tab_Base[[Categoria]:[Categoria]],$B6,Tab_Base[[Mês]:[Mês]],N$3,Tab_Base[[Ano]:[Ano]],$B$3,Tab_Base[[Tipo]:[Tipo]],"Saída") -> 0 | O9: =SUM(tb_saidas[[#This Row],[Janeiro]:[Dezembro]]) -> 3132.95 | P9: =SUMIFS(Tab_Base[Valor],Tab_Base[Categoria],tb_saidas[[#This Row],[Saídas]],Tab_Base[Data],">="&$P$2,Tab_Base[Data],"<="&$P$3,Tab_Base[Tipo],"Saída") -> 320
B10: Outros | C10: =SUMIFS(Tab_Base[[Valor]:[Valor]],Tab_Base[[Categoria]:[Categoria]],#REF!,Tab_Base[[Mês]:[Mês]],C$3,Tab_Base[[Ano]:[Ano]],$B$3,Tab_Base[[Tipo]:[Tipo]],"Saída") -> 0 | D10: =SUMIFS(Tab_Base[[Valor]:[Valor]],Tab_Base[[Categoria]:[Categoria]],#REF!,Tab_Base[[Mês]:[Mês]],D$3,Tab_Base[[Ano]:[Ano]],$B$3,Tab_Base[[Tipo]:[Tipo]],"Saída") -> 0 | E10: =SUMIFS(Tab_Base[[Valor]:[Valor]],Tab_Base[[Categoria]:[Categoria]],#REF!,Tab_Base[[Mês]:[Mês]],E$3,Tab_Base[[Ano]:[Ano]],$B$3,Tab_Base[[Tipo]:[Tipo]],"Saída") -> 0 | F10: =SUMIFS(Tab_Base[[Valor]:[Valor]],Tab_Base[[Categoria]:[Categoria]],#REF!,Tab_Base[[Mês]:[Mês]],F$3,Tab_Base[[Ano]:[Ano]],$B$3,Tab_Base[[Tipo]:[Tipo]],"Saída") -> 0 | G10: =SUMIFS(Tab_Base[[Valor]:[Valor]],Tab_Base[[Categoria]:[Categoria]],#REF!,Tab_Base[[Mês]:[Mês]],G$3,Tab_Base[[Ano]:[Ano]],$B$3,Tab_Base[[Tipo]:[Tipo]],"Saída") -> 0 | H10: =SUMIFS(Tab_Base[[Valor]:[Valor]],Tab_Base[[Categoria]:[Categoria]],#REF!,Tab_Base[[Mês]:[Mês]],H$3,Tab_Base[[Ano]:[Ano]],$B$3,Tab_Base[[Tipo]:[Tipo]],"Saída") -> 0 | I10: =SUMIFS(Tab_Base[[Valor]:[Valor]],Tab_Base[[Categoria]:[Categoria]],#REF!,Tab_Base[[Mês]:[Mês]],I$3,Tab_Base[[Ano]:[Ano]],$B$3,Tab_Base[[Tipo]:[Tipo]],"Saída") -> 0 | J10: =SUMIFS(Tab_Base[[Valor]:[Valor]],Tab_Base[[Categoria]:[Categoria]],#REF!,Tab_Base[[Mês]:[Mês]],J$3,Tab_Base[[Ano]:[Ano]],$B$3,Tab_Base[[Tipo]:[Tipo]],"Saída") -> 0 | ... N10: =SUMIFS(Tab_Base[[Valor]:[Valor]],Tab_Base[[Categoria]:[Categoria]],#REF!,Tab_Base[[Mês]:[Mês]],N$3,Tab_Base[[Ano]:[Ano]],$B$3,Tab_Base[[Tipo]:[Tipo]],"Saída") -> 0 | O10: =SUM(tb_saidas[[#This Row],[Janeiro]:[Dezembro]]) -> 0 | P10: =SUMIFS(Tab_Base[Valor],Tab_Base[Categoria],tb_saidas[[#This Row],[Saídas]],Tab_Base[Data],">="&$P$2,Tab_Base[Data],"<="&$P$3,Tab_Base[Tipo],"Saída") -> 201
B11: Parcela CNH | C11: =SUMIFS(Tab_Base[[Valor]:[Valor]],Tab_Base[[Categoria]:[Categoria]],$B8,Tab_Base[[Mês]:[Mês]],C$3,Tab_Base[[Ano]:[Ano]],$B$3,Tab_Base[[Tipo]:[Tipo]],"Saída") -> 0 | D11: =SUMIFS(Tab_Base[[Valor]:[Valor]],Tab_Base[[Categoria]:[Categoria]],$B8,Tab_Base[[Mês]:[Mês]],D$3,Tab_Base[[Ano]:[Ano]],$B$3,Tab_Base[[Tipo]:[Tipo]],"Saída") -> 0 | E11: =SUMIFS(Tab_Base[[Valor]:[Valor]],Tab_Base[[Categoria]:[Categoria]],$B8,Tab_Base[[Mês]:[Mês]],E$3,Tab_Base[[Ano]:[Ano]],$B$3,Tab_Base[[Tipo]:[Tipo]],"Saída") -> 0 | F11: =SUMIFS(Tab_Base[[Valor]:[Valor]],Tab_Base[[Categoria]:[Categoria]],$B8,Tab_Base[[Mês]:[Mês]],F$3,Tab_Base[[Ano]:[Ano]],$B$3,Tab_Base[[Tipo]:[Tipo]],"Saída") -> 0 | G11: =SUMIFS(Tab_Base[[Valor]:[Valor]],Tab_Base[[Categoria]:[Categoria]],$B8,Tab_Base[[Mês]:[Mês]],G$3,Tab_Base[[Ano]:[Ano]],$B$3,Tab_Base[[Tipo]:[Tipo]],"Saída") -> 0 | H11: =SUMIFS(Tab_Base[[Valor]:[Valor]],Tab_Base[[Categoria]:[Categoria]],$B8,Tab_Base[[Mês]:[Mês]],H$3,Tab_Base[[Ano]:[Ano]],$B$3,Tab_Base[[Tipo]:[Tipo]],"Saída") -> 0 | I11: =SUMIFS(Tab_Base[[Valor]:[Valor]],Tab_Base[[Categoria]:[Categoria]],$B8,Tab_Base[[Mês]:[Mês]],I$3,Tab_Base[[Ano]:[Ano]],$B$3,Tab_Base[[Tipo]:[Tipo]],"Saída") -> 0 | J11: =SUMIFS(Tab_Base[[Valor]:[Valor]],Tab_Base[[Categoria]:[Categoria]],$B8,Tab_Base[[Mês]:[Mês]],J$3,Tab_Base[[Ano]:[Ano]],$B$3,Tab_Base[[Tipo]:[Tipo]],"Saída") -> 0 | ... N11: =SUMIFS(Tab_Base[[Valor]:[Valor]],Tab_Base[[Categoria]:[Categoria]],$B8,Tab_Base[[Mês]:[Mês]],N$3,Tab_Base[[Ano]:[Ano]],$B$3,Tab_Base[[Tipo]:[Tipo]],"Saída") -> 0 | O11: =SUM(tb_saidas[[#This Row],[Janeiro]:[Dezembro]]) -> 330 | P11: =SUMIFS(Tab_Base[Valor],Tab_Base[Categoria],tb_saidas[[#This Row],[Saídas]],Tab_Base[Data],">="&$P$2,Tab_Base[Data],"<="&$P$3,Tab_Base[Tipo],"Saída") -> 388
B12: Pix Anderson | C12: =SUMIFS(Tab_Base[[Valor]:[Valor]],Tab_Base[[Categoria]:[Categoria]],$B9,Tab_Base[[Mês]:[Mês]],C$3,Tab_Base[[Ano]:[Ano]],$B$3,Tab_Base[[Tipo]:[Tipo]],"Saída") -> 0 | D12: =SUMIFS(Tab_Base[[Valor]:[Valor]],Tab_Base[[Categoria]:[Categoria]],$B9,Tab_Base[[Mês]:[Mês]],D$3,Tab_Base[[Ano]:[Ano]],$B$3,Tab_Base[[Tipo]:[Tipo]],"Saída") -> 0 | E12: =SUMIFS(Tab_Base[[Valor]:[Valor]],Tab_Base[[Categoria]:[Categoria]],$B9,Tab_Base[[Mês]:[Mês]],E$3,Tab_Base[[Ano]:[Ano]],$B$3,Tab_Base[[Tipo]:[Tipo]],"Saída") -> 0 | F12: =SUMIFS(Tab_Base[[Valor]:[Valor]],Tab_Base[[Categoria]:[Categoria]],$B9,Tab_Base[[Mês]:[Mês]],F$3,Tab_Base[[Ano]:[Ano]],$B$3,Tab_Base[[Tipo]:[Tipo]],"Saída") -> 0 | G12: =SUMIFS(Tab_Base[[Valor]:[Valor]],Tab_Base[[Categoria]:[Categoria]],$B9,Tab_Base[[Mês]:[Mês]],G$3,Tab_Base[[Ano]:[Ano]],$B$3,Tab_Base[[Tipo]:[Tipo]],"Saída") -> 0 | H12: =SUMIFS(Tab_Base[[Valor]:[Valor]],Tab_Base[[Categoria]:[Categoria]],$B9,Tab_Base[[Mês]:[Mês]],H$3,Tab_Base[[Ano]:[Ano]],$B$3,Tab_Base[[Tipo]:[Tipo]],"Saída") -> 0 | I12: =SUMIFS(Tab_Base[[Valor]:[Valor]],Tab_Base[[Categoria]:[Categoria]],$B9,Tab_Base[[Mês]:[Mês]],I$3,Tab_Base[[Ano]:[Ano]],$B$3,Tab_Base[[Tipo]:[Tipo]],"Saída") -> 0 | J12: =SUMIFS(Tab_Base[[Valor]:[Valor]],Tab_Base[[Categoria]:[Categoria]],$B9,Tab_Base[[Mês]:[Mês]],J$3,Tab_Base[[Ano]:[Ano]],$B$3,Tab_Base[[Tipo]:[Tipo]],"Saída") -> 0 | ... N12: =SUMIFS(Tab_Base[[Valor]:[Valor]],Tab_Base[[Categoria]:[Categoria]],$B9,Tab_Base[[Mês]:[Mês]],N$3,Tab_Base[[Ano]:[Ano]],$B$3,Tab_Base[[Tipo]:[Tipo]],"Saída") -> 0 | O12: =SUM(tb_saidas[[#This Row],[Janeiro]:[Dezembro]]) -> 320 | P12: =SUMIFS(Tab_Base[Valor],Tab_Base[Categoria],tb_saidas[[#This Row],[Saídas]],Tab_Base[Data],">="&$P$2,Tab_Base[Data],"<="&$P$3,Tab_Base[Tipo],"Saída") -> 200
B13: Mercado | C13: =SUMIFS(Tab_Base[[Valor]:[Valor]],Tab_Base[[Categoria]:[Categoria]],#REF!,Tab_Base[[Mês]:[Mês]],C$3,Tab_Base[[Ano]:[Ano]],$B$3,Tab_Base[[Tipo]:[Tipo]],"Saída") -> 0 | D13: =SUMIFS(Tab_Base[[Valor]:[Valor]],Tab_Base[[Categoria]:[Categoria]],#REF!,Tab_Base[[Mês]:[Mês]],D$3,Tab_Base[[Ano]:[Ano]],$B$3,Tab_Base[[Tipo]:[Tipo]],"Saída") -> 0 | E13: =SUMIFS(Tab_Base[[Valor]:[Valor]],Tab_Base[[Categoria]:[Categoria]],#REF!,Tab_Base[[Mês]:[Mês]],E$3,Tab_Base[[Ano]:[Ano]],$B$3,Tab_Base[[Tipo]:[Tipo]],"Saída") -> 0 | F13: =SUMIFS(Tab_Base[[Valor]:[Valor]],Tab_Base[[Categoria]:[Categoria]],#REF!,Tab_Base[[Mês]:[Mês]],F$3,Tab_Base[[Ano]:[Ano]],$B$3,Tab_Base[[Tipo]:[Tipo]],"Saída") -> 0 | G13: =SUMIFS(Tab_Base[[Valor]:[Valor]],Tab_Base[[Categoria]:[Categoria]],#REF!,Tab_Base[[Mês]:[Mês]],G$3,Tab_Base[[Ano]:[Ano]],$B$3,Tab_Base[[Tipo]:[Tipo]],"Saída") -> 0 | H13: =SUMIFS(Tab_Base[[Valor]:[Valor]],Tab_Base[[Categoria]:[Categoria]],#REF!,Tab_Base[[Mês]:[Mês]],H$3,Tab_Base[[Ano]:[Ano]],$B$3,Tab_Base[[Tipo]:[Tipo]],"Saída") -> 0 | I13: =SUMIFS(Tab_Base[[Valor]:[Valor]],Tab_Base[[Categoria]:[Categoria]],#REF!,Tab_Base[[Mês]:[Mês]],I$3,Tab_Base[[Ano]:[Ano]],$B$3,Tab_Base[[Tipo]:[Tipo]],"Saída") -> 0 | J13: =SUMIFS(Tab_Base[[Valor]:[Valor]],Tab_Base[[Categoria]:[Categoria]],#REF!,Tab_Base[[Mês]:[Mês]],J$3,Tab_Base[[Ano]:[Ano]],$B$3,Tab_Base[[Tipo]:[Tipo]],"Saída") -> 0 | ... N13: =SUMIFS(Tab_Base[[Valor]:[Valor]],Tab_Base[[Categoria]:[Categoria]],#REF!,Tab_Base[[Mês]:[Mês]],N$3,Tab_Base[[Ano]:[Ano]],$B$3,Tab_Base[[Tipo]:[Tipo]],"Saída") -> 0 | O13: =SUM(tb_saidas[[#This Row],[Janeiro]:[Dezembro]]) -> 0 | P13: =SUMIFS(Tab_Base[Valor],Tab_Base[Categoria],tb_saidas[[#This Row],[Saídas]],Tab_Base[Data],">="&$P$2,Tab_Base[Data],"<="&$P$3,Tab_Base[Tipo],"Saída") -> 44.78
B14: Cantina Microlins | C14: =SUMIFS(Tab_Base[[Valor]:[Valor]],Tab_Base[[Categoria]:[Categoria]],$B11,Tab_Base[[Mês]:[Mês]],C$3,Tab_Base[[Ano]:[Ano]],$B$3,Tab_Base[[Tipo]:[Tipo]],"Saída") -> 0 | D14: =SUMIFS(Tab_Base[[Valor]:[Valor]],Tab_Base[[Categoria]:[Categoria]],$B11,Tab_Base[[Mês]:[Mês]],D$3,Tab_Base[[Ano]:[Ano]],$B$3,Tab_Base[[Tipo]:[Tipo]],"Saída") -> 0 | E14: =SUMIFS(Tab_Base[[Valor]:[Valor]],Tab_Base[[Categoria]:[Categoria]],$B11,Tab_Base[[Mês]:[Mês]],E$3,Tab_Base[[Ano]:[Ano]],$B$3,Tab_Base[[Tipo]:[Tipo]],"Saída") -> 0 | F14: =SUMIFS(Tab_Base[[Valor]:[Valor]],Tab_Base[[Categoria]:[Categoria]],$B11,Tab_Base[[Mês]:[Mês]],F$3,Tab_Base[[Ano]:[Ano]],$B$3,Tab_Base[[Tipo]:[Tipo]],"Saída") -> 0 | G14: =SUMIFS(Tab_Base[[Valor]:[Valor]],Tab_Base[[Categoria]:[Categoria]],$B11,Tab_Base[[Mês]:[Mês]],G$3,Tab_Base[[Ano]:[Ano]],$B$3,Tab_Base[[Tipo]:[Tipo]],"Saída") -> 0 | H14: =SUMIFS(Tab_Base[[Valor]:[Valor]],Tab_Base[[Categoria]:[Categoria]],$B11,Tab_Base[[Mês]:[Mês]],H$3,Tab_Base[[Ano]:[Ano]],$B$3,Tab_Base[[Tipo]:[Tipo]],"Saída") -> 0 | I14: =SUMIFS(Tab_Base[[Valor]:[Valor]],Tab_Base[[Categoria]:[Categoria]],$B11,Tab_Base[[Mês]:[Mês]],I$3,Tab_Base[[Ano]:[Ano]],$B$3,Tab_Base[[Tipo]:[Tipo]],"Saída") -> 0 | J14: =SUMIFS(Tab_Base[[Valor]:[Valor]],Tab_Base[[Categoria]:[Categoria]],$B11,Tab_Base[[Mês]:[Mês]],J$3,Tab_Base[[Ano]:[Ano]],$B$3,Tab_Base[[Tipo]:[Tipo]],"Saída") -> 0 | ... N14: =SUMIFS(Tab_Base[[Valor]:[Valor]],Tab_Base[[Categoria]:[Categoria]],$B11,Tab_Base[[Mês]:[Mês]],N$3,Tab_Base[[Ano]:[Ano]],$B$3,Tab_Base[[Tipo]:[Tipo]],"Saída") -> 0 | O14: =SUM(tb_saidas[[#This Row],[Janeiro]:[Dezembro]]) -> 388 | P14: =SUMIFS(Tab_Base[Valor],Tab_Base[Categoria],tb_saidas[[#This Row],[Saídas]],Tab_Base[Data],">="&$P$2,Tab_Base[Data],"<="&$P$3,Tab_Base[Tipo],"Saída") -> 9.15
B15: Cabelo | C15: =SUMIFS(Tab_Base[[Valor]:[Valor]],Tab_Base[[Categoria]:[Categoria]],$B12,Tab_Base[[Mês]:[Mês]],C$3,Tab_Base[[Ano]:[Ano]],$B$3,Tab_Base[[Tipo]:[Tipo]],"Saída") -> 0 | D15: =SUMIFS(Tab_Base[[Valor]:[Valor]],Tab_Base[[Categoria]:[Categoria]],$B12,Tab_Base[[Mês]:[Mês]],D$3,Tab_Base[[Ano]:[Ano]],$B$3,Tab_Base[[Tipo]:[Tipo]],"Saída") -> 0 | E15: =SUMIFS(Tab_Base[[Valor]:[Valor]],Tab_Base[[Categoria]:[Categoria]],$B12,Tab_Base[[Mês]:[Mês]],E$3,Tab_Base[[Ano]:[Ano]],$B$3,Tab_Base[[Tipo]:[Tipo]],"Saída") -> 0 | F15: =SUMIFS(Tab_Base[[Valor]:[Valor]],Tab_Base[[Categoria]:[Categoria]],$B12,Tab_Base[[Mês]:[Mês]],F$3,Tab_Base[[Ano]:[Ano]],$B$3,Tab_Base[[Tipo]:[Tipo]],"Saída") -> 0 | G15: =SUMIFS(Tab_Base[[Valor]:[Valor]],Tab_Base[[Categoria]:[Categoria]],$B12,Tab_Base[[Mês]:[Mês]],G$3,Tab_Base[[Ano]:[Ano]],$B$3,Tab_Base[[Tipo]:[Tipo]],"Saída") -> 0 | H15: =SUMIFS(Tab_Base[[Valor]:[Valor]],Tab_Base[[Categoria]:[Categoria]],$B12,Tab_Base[[Mês]:[Mês]],H$3,Tab_Base[[Ano]:[Ano]],$B$3,Tab_Base[[Tipo]:[Tipo]],"Saída") -> 0 | I15: =SUMIFS(Tab_Base[[Valor]:[Valor]],Tab_Base[[Categoria]:[Categoria]],$B12,Tab_Base[[Mês]:[Mês]],I$3,Tab_Base[[Ano]:[Ano]],$B$3,Tab_Base[[Tipo]:[Tipo]],"Saída") -> 0 | J15: =SUMIFS(Tab_Base[[Valor]:[Valor]],Tab_Base[[Categoria]:[Categoria]],$B12,Tab_Base[[Mês]:[Mês]],J$3,Tab_Base[[Ano]:[Ano]],$B$3,Tab_Base[[Tipo]:[Tipo]],"Saída") -> 0 | ... N15: =SUMIFS(Tab_Base[[Valor]:[Valor]],Tab_Base[[Categoria]:[Categoria]],$B12,Tab_Base[[Mês]:[Mês]],N$3,Tab_Base[[Ano]:[Ano]],$B$3,Tab_Base[[Tipo]:[Tipo]],"Saída") -> 0 | O15: =SUM(tb_saidas[[#This Row],[Janeiro]:[Dezembro]]) -> 200 | P15: =SUMIFS(Tab_Base[Valor],Tab_Base[Categoria],tb_saidas[[#This Row],[Saídas]],Tab_Base[Data],">="&$P$2,Tab_Base[Data],"<="&$P$3,Tab_Base[Tipo],"Saída") -> 50
B16: Resgate RDB | C16: =SUMIFS(Tab_Base[[Valor]:[Valor]],Tab_Base[[Categoria]:[Categoria]],$B16,Tab_Base[[Mês]:[Mês]],C$3,Tab_Base[[Ano]:[Ano]],$B$3,Tab_Base[[Tipo]:[Tipo]],"Saída") -> 0 | D16: =SUMIFS(Tab_Base[[Valor]:[Valor]],Tab_Base[[Categoria]:[Categoria]],$B16,Tab_Base[[Mês]:[Mês]],D$3,Tab_Base[[Ano]:[Ano]],$B$3,Tab_Base[[Tipo]:[Tipo]],"Saída") -> 0 | E16: =SUMIFS(Tab_Base[[Valor]:[Valor]],Tab_Base[[Categoria]:[Categoria]],$B16,Tab_Base[[Mês]:[Mês]],E$3,Tab_Base[[Ano]:[Ano]],$B$3,Tab_Base[[Tipo]:[Tipo]],"Saída") -> 0 | F16: =SUMIFS(Tab_Base[[Valor]:[Valor]],Tab_Base[[Categoria]:[Categoria]],$B16,Tab_Base[[Mês]:[Mês]],F$3,Tab_Base[[Ano]:[Ano]],$B$3,Tab_Base[[Tipo]:[Tipo]],"Saída") -> 0 | G16: =SUMIFS(Tab_Base[[Valor]:[Valor]],Tab_Base[[Categoria]:[Categoria]],$B16,Tab_Base[[Mês]:[Mês]],G$3,Tab_Base[[Ano]:[Ano]],$B$3,Tab_Base[[Tipo]:[Tipo]],"Saída") -> 0 | H16: =SUMIFS(Tab_Base[[Valor]:[Valor]],Tab_Base[[Categoria]:[Categoria]],$B16,Tab_Base[[Mês]:[Mês]],H$3,Tab_Base[[Ano]:[Ano]],$B$3,Tab_Base[[Tipo]:[Tipo]],"Saída") -> 0 | I16: =SUMIFS(Tab_Base[[Valor]:[Valor]],Tab_Base[[Categoria]:[Categoria]],$B16,Tab_Base[[Mês]:[Mês]],I$3,Tab_Base[[Ano]:[Ano]],$B$3,Tab_Base[[Tipo]:[Tipo]],"Saída") -> 0 | J16: =SUMIFS(Tab_Base[[Valor]:[Valor]],Tab_Base[[Categoria]:[Categoria]],$B16,Tab_Base[[Mês]:[Mês]],J$3,Tab_Base[[Ano]:[Ano]],$B$3,Tab_Base[[Tipo]:[Tipo]],"Saída") -> 0 | ... N16: =SUMIFS(Tab_Base[[Valor]:[Valor]],Tab_Base[[Categoria]:[Categoria]],$B16,Tab_Base[[Mês]:[Mês]],N$3,Tab_Base[[Ano]:[Ano]],$B$3,Tab_Base[[Tipo]:[Tipo]],"Saída") -> 0 | O16: =SUM(tb_saidas[[#This Row],[Janeiro]:[Dezembro]]) -> 0 | P16: =SUMIFS(Tab_Base[Valor],Tab_Base[Categoria],tb_saidas[[#This Row],[Saídas]],Tab_Base[Data],">="&$P$2,Tab_Base[Data],"<="&$P$3,Tab_Base[Tipo],"Saída") -> 0
C17: =SUMIFS(Tab_Base[[Valor]:[Valor]],Tab_Base[[Categoria]:[Categoria]],$B17,Tab_Base[[Mês]:[Mês]],C$3,Tab_Base[[Ano]:[Ano]],$B$3,Tab_Base[[Tipo]:[Tipo]],"Saída") -> 0 | D17: =SUMIFS(Tab_Base[[Valor]:[Valor]],Tab_Base[[Categoria]:[Categoria]],$B17,Tab_Base[[Mês]:[Mês]],D$3,Tab_Base[[Ano]:[Ano]],$B$3,Tab_Base[[Tipo]:[Tipo]],"Saída") -> 0 | E17: =SUMIFS(Tab_Base[[Valor]:[Valor]],Tab_Base[[Categoria]:[Categoria]],$B17,Tab_Base[[Mês]:[Mês]],E$3,Tab_Base[[Ano]:[Ano]],$B$3,Tab_Base[[Tipo]:[Tipo]],"Saída") -> 0 | F17: =SUMIFS(Tab_Base[[Valor]:[Valor]],Tab_Base[[Categoria]:[Categoria]],$B17,Tab_Base[[Mês]:[Mês]],F$3,Tab_Base[[Ano]:[Ano]],$B$3,Tab_Base[[Tipo]:[Tipo]],"Saída") -> 0 | G17: =SUMIFS(Tab_Base[[Valor]:[Valor]],Tab_Base[[Categoria]:[Categoria]],$B17,Tab_Base[[Mês]:[Mês]],G$3,Tab_Base[[Ano]:[Ano]],$B$3,Tab_Base[[Tipo]:[Tipo]],"Saída") -> 0 | H17: =SUMIFS(Tab_Base[[Valor]:[Valor]],Tab_Base[[Categoria]:[Categoria]],$B17,Tab_Base[[Mês]:[Mês]],H$3,Tab_Base[[Ano]:[Ano]],$B$3,Tab_Base[[Tipo]:[Tipo]],"Saída") -> 0 | I17: =SUMIFS(Tab_Base[[Valor]:[Valor]],Tab_Base[[Categoria]:[Categoria]],$B17,Tab_Base[[Mês]:[Mês]],I$3,Tab_Base[[Ano]:[Ano]],$B$3,Tab_Base[[Tipo]:[Tipo]],"Saída") -> 0 | J17: =SUMIFS(Tab_Base[[Valor]:[Valor]],Tab_Base[[Categoria]:[Categoria]],$B17,Tab_Base[[Mês]:[Mês]],J$3,Tab_Base[[Ano]:[Ano]],$B$3,Tab_Base[[Tipo]:[Tipo]],"Saída") -> 0 | ... N17: =SUMIFS(Tab_Base[[Valor]:[Valor]],Tab_Base[[Categoria]:[Categoria]],$B17,Tab_Base[[Mês]:[Mês]],N$3,Tab_Base[[Ano]:[Ano]],$B$3,Tab_Base[[Tipo]:[Tipo]],"Saída") -> 0 | O17: =SUM(tb_saidas[[#This Row],[Janeiro]:[Dezembro]]) -> 0 | P17: =SUMIFS(Tab_Base[Valor],Tab_Base[Categoria],tb_saidas[[#This Row],[Saídas]],Tab_Base[Data],">="&$P$2,Tab_Base[Data],"<="&$P$3,Tab_Base[Tipo],"Saída") -> 0
C18: =SUMIFS(Tab_Base[[Valor]:[Valor]],Tab_Base[[Categoria]:[Categoria]],$B18,Tab_Base[[Mês]:[Mês]],C$3,Tab_Base[[Ano]:[Ano]],$B$3,Tab_Base[[Tipo]:[Tipo]],"Saída") -> 0 | D18: =SUMIFS(Tab_Base[[Valor]:[Valor]],Tab_Base[[Categoria]:[Categoria]],$B18,Tab_Base[[Mês]:[Mês]],D$3,Tab_Base[[Ano]:[Ano]],$B$3,Tab_Base[[Tipo]:[Tipo]],"Saída") -> 0 | E18: =SUMIFS(Tab_Base[[Valor]:[Valor]],Tab_Base[[Categoria]:[Categoria]],$B18,Tab_Base[[Mês]:[Mês]],E$3,Tab_Base[[Ano]:[Ano]],$B$3,Tab_Base[[Tipo]:[Tipo]],"Saída") -> 0 | F18: =SUMIFS(Tab_Base[[Valor]:[Valor]],Tab_Base[[Categoria]:[Categoria]],$B18,Tab_Base[[Mês]:[Mês]],F$3,Tab_Base[[Ano]:[Ano]],$B$3,Tab_Base[[Tipo]:[Tipo]],"Saída") -> 0 | G18: =SUMIFS(Tab_Base[[Valor]:[Valor]],Tab_Base[[Categoria]:[Categoria]],$B18,Tab_Base[[Mês]:[Mês]],G$3,Tab_Base[[Ano]:[Ano]],$B$3,Tab_Base[[Tipo]:[Tipo]],"Saída") -> 0 | H18: =SUMIFS(Tab_Base[[Valor]:[Valor]],Tab_Base[[Categoria]:[Categoria]],$B18,Tab_Base[[Mês]:[Mês]],H$3,Tab_Base[[Ano]:[Ano]],$B$3,Tab_Base[[Tipo]:[Tipo]],"Saída") -> 0 | I18: =SUMIFS(Tab_Base[[Valor]:[Valor]],Tab_Base[[Categoria]:[Categoria]],$B18,Tab_Base[[Mês]:[Mês]],I$3,Tab_Base[[Ano]:[Ano]],$B$3,Tab_Base[[Tipo]:[Tipo]],"Saída") -> 0 | J18: =SUMIFS(Tab_Base[[Valor]:[Valor]],Tab_Base[[Categoria]:[Categoria]],$B18,Tab_Base[[Mês]:[Mês]],J$3,Tab_Base[[Ano]:[Ano]],$B$3,Tab_Base[[Tipo]:[Tipo]],"Saída") -> 0 | ... N18: =SUMIFS(Tab_Base[[Valor]:[Valor]],Tab_Base[[Categoria]:[Categoria]],$B18,Tab_Base[[Mês]:[Mês]],N$3,Tab_Base[[Ano]:[Ano]],$B$3,Tab_Base[[Tipo]:[Tipo]],"Saída") -> 0 | O18: =SUM(tb_saidas[[#This Row],[Janeiro]:[Dezembro]]) -> 0 | P18: =SUMIFS(Tab_Base[Valor],Tab_Base[Categoria],tb_saidas[[#This Row],[Saídas]],Tab_Base[Data],">="&$P$2,Tab_Base[Data],"<="&$P$3,Tab_Base[Tipo],"Saída") -> 0
C19: =SUMIFS(Tab_Base[[Valor]:[Valor]],Tab_Base[[Categoria]:[Categoria]],$B19,Tab_Base[[Mês]:[Mês]],C$3,Tab_Base[[Ano]:[Ano]],$B$3,Tab_Base[[Tipo]:[Tipo]],"Saída") -> 0 | D19: =SUMIFS(Tab_Base[[Valor]:[Valor]],Tab_Base[[Categoria]:[Categoria]],$B19,Tab_Base[[Mês]:[Mês]],D$3,Tab_Base[[Ano]:[Ano]],$B$3,Tab_Base[[Tipo]:[Tipo]],"Saída") -> 0 | E19: =SUMIFS(Tab_Base[[Valor]:[Valor]],Tab_Base[[Categoria]:[Categoria]],$B19,Tab_Base[[Mês]:[Mês]],E$3,Tab_Base[[Ano]:[Ano]],$B$3,Tab_Base[[Tipo]:[Tipo]],"Saída") -> 0 | F19: =SUMIFS(Tab_Base[[Valor]:[Valor]],Tab_Base[[Categoria]:[Categoria]],$B19,Tab_Base[[Mês]:[Mês]],F$3,Tab_Base[[Ano]:[Ano]],$B$3,Tab_Base[[Tipo]:[Tipo]],"Saída") -> 0 | G19: =SUMIFS(Tab_Base[[Valor]:[Valor]],Tab_Base[[Categoria]:[Categoria]],$B19,Tab_Base[[Mês]:[Mês]],G$3,Tab_Base[[Ano]:[Ano]],$B$3,Tab_Base[[Tipo]:[Tipo]],"Saída") -> 0 | H19: =SUMIFS(Tab_Base[[Valor]:[Valor]],Tab_Base[[Categoria]:[Categoria]],$B19,Tab_Base[[Mês]:[Mês]],H$3,Tab_Base[[Ano]:[Ano]],$B$3,Tab_Base[[Tipo]:[Tipo]],"Saída") -> 0 | I19: =SUMIFS(Tab_Base[[Valor]:[Valor]],Tab_Base[[Categoria]:[Categoria]],$B19,Tab_Base[[Mês]:[Mês]],I$3,Tab_Base[[Ano]:[Ano]],$B$3,Tab_Base[[Tipo]:[Tipo]],"Saída") -> 0 | J19: =SUMIFS(Tab_Base[[Valor]:[Valor]],Tab_Base[[Categoria]:[Categoria]],$B19,Tab_Base[[Mês]:[Mês]],J$3,Tab_Base[[Ano]:[Ano]],$B$3,Tab_Base[[Tipo]:[Tipo]],"Saída") -> 0 | ... N19: =SUMIFS(Tab_Base[[Valor]:[Valor]],Tab_Base[[Categoria]:[Categoria]],$B19,Tab_Base[[Mês]:[Mês]],N$3,Tab_Base[[Ano]:[Ano]],$B$3,Tab_Base[[Tipo]:[Tipo]],"Saída") -> 0 | O19: =SUM(tb_saidas[[#This Row],[Janeiro]:[Dezembro]]) -> 0 | P19: =SUMIFS(Tab_Base[Valor],Tab_Base[Categoria],tb_saidas[[#This Row],[Saídas]],Tab_Base[Data],">="&$P$2,Tab_Base[Data],"<="&$P$3,Tab_Base[Tipo],"Saída") -> 0
